Workbook

Sheet Theorie
A2: Digital Power Competentiehuis | J2: Competentiegebieden

Sheet Vragenlijst
A1: Vragenlijst
A3: Voorbeeld competentiegebied | B3: Vul per situatie de corresponderende invulwaarde in bij de best passende competentie beschrijving | F3: Invulinstructie
A4: Voorbeeld competentie | B4: Competentieniveau tot heden | C4: Wenselijk competentieniveau | D4: Invulwaarde | F4: Ieder competentiegebied (6), te herkennen aan de verschillende kleuren, bestaat uit een aantal specifieke competenties. Bepaal voor iedere competentie waar je ambitie (wenselijk competenieniveau) ligt en waar je nu staat (competentieniveau tot heden). - Doe dit door jezelf te scoren op de aangegeven schaal (zie voorbeeld) - Indien je (nu) geen ambitie hebt op een competentie, hou je de score aan die weergeeft wat je competentieniveau tot heden is. Bepaal bij iedere competentie welke beschrijvng het beste past voor de situatie (heden/ wens). Kijk niet alleen naar kennis en kunde, maar ook naar invloedssfeer en mate aan (persoonlijk) leiderschap in je rol bij de klant. Creeer je gewenste profiel aan de hand van je ambitie! En ontwikkel díe competenties die invulling geven aan het verwezenlijken van deze ambitie. Het doel is niet om te toetsen of je wel/ geen goede consultant bent binnen dit domein. Het doel is wel dat je competenties ontwikkelt die bij jouw ambitie passen. Wees realitisch bij het invullen. Alleen dan gebruik je het tot de volle potentie. Succes met invullen!
A5: Voorbeeld competentie beschrijving: Acteert bij klanten op competentie A. | D5: 1
A6: Voorbeeld competentie beschrijving: Acteert bij klanten naast compententie A, ook op competentie B. | B6: 3 | D6: 2
A7: Voorbeeld competentie beschrijving: Acteert bij klanten naast compententie A en B, ook op competentie C. | B7: 3 | C7: 5 | D7: 3
A8: Voorbeeld competentie beschrijving: Acteert bij klanten naast compententie A, B en C, ook op competentie D. | C8: 4 | D8: 4
A9: Voorbeeld competentie beschrijving: Acteert bij klanten naast compententie A, B, C en D, ook op competentie E. | D9: 5
A11: Competentiegebied: Digital Power basis competenties
A12: Leren & reflecteren | B12: Competentieniveau tot heden | C12: Wenselijk competentieniveau | D12: Invulwaarde
A13: Heeft een groei mindset | D13: 1
A14: Ontvangt positieve en opbouwende feedback met een open houding, is in staat dit voor zelfreflectie te gebruiken, het op te nemen in zijn/ haar eigen ontwikkeling en hier de nodige ontwikkeling op te ondernemen met trainingen en cursussen. | D14: 2
A15: Is naast bovengenoemde externe prikkel (feedback van anderen), in staat zelf kritisch te blijven op eigen kennis en ervaring en het eventueel ontbreken ervan. Neemt hierin de nodige acties en neemt daarin zelf de regie over de eigen ontwikkeling. | D15: 3
A16: Neemt een voorbeeldrol aan in bovengenoemde competenties en draagt deze eveneens actief uit vanuit de begeleidende rol naar juniors en mediors. | D16: 4
A17: Neemt een leidersrol aan in bovengenoemde competenties en draagt deze actief uit vanuit de begeleidersrol en/ of als organisatieverantwoordelijke. | D17: 5
A19: Ondersteunen & samenwerken | B19: Competentieniveau tot heden | C19: Wenselijk competentieniveau | D19: Invulwaarde
A20: Heeft een collegiale mindset | D20: 1
A21: Is behulpzaam en betrokken naar zowel interne als externe collega's | D21: 2
A22: Zoekt actief de samenwerking op. Zowel binnen als buiten het eigen team waarin je (tijdelijk) onderdeel van uitmaakt. | D22: 3
A23: Neemt een voorbeeld rol in bij het zoeken naar samenwerking. Neemt de verantwoordelijkheid op zich om anderen te ondersteunen en de hulp te bieden om ervoor te zorgen dat teamleden zelfredzaam worden in hun werkzaamheden. | D23: 4
A24: … | D24: 5
A26: Ondernemen & resultaatgericht | B26: Competentieniveau tot heden | C26: Wenselijk competentieniveau | D26: Invulwaarde
A27: Heeft een ondernemende & resultaatgerichte mindset | D27: 1
A28: Gericht op effectief handelen en het op tijd opleveren van afgesproken werk, binnen de afgesproken tijd. | D28: 2
A29: Naast bovengenoemde competenties in staat kansen te herkennen en actief te handelen om klanten te helpen en/ of DiP verder te profilen. Is in staat klantdoelstellingen te vertalen naar concrete en praktische acties. | D29: 3
A30: Naast bovengenoemde competenties in staat commerciele activiteiten (zoals het uitbouwen van uren, additionele opdrachten genereren ed.) te verhogen. Ontplooit binnen DiP projecten en overziet en/ of begeleidt deze naar het beoogde resultaat. | D30: 4
A31: Naast bovengenoemde competenties verantwoordelijk voor de ontwikkeling van een specialisme binnen DiP. Incl. het monitoren en marktconform houden van dit specialisme. | D31: 5
A33: Klantgericht | B33: Competentieniveau tot heden | C33: Wenselijk competentieniveau | D33: Invulwaarde
A34: Heeft een klantgerichte mindset | D34: 1
A35: Herkent behoeften en belangen van de klant; stelt zich hulpvaardig op en houdt in het handelen rekening met de behoeften en belangen van de klant. | D35: 2
A36: Denkt naast bovengenoemde competenties, actief mee met de klant. Deelt inzichten in de klantorganisatie binnen DiP om commerciële activiteiten verder uit te kunnen breiden. Streeft daarin actief naar verhoging van klanttevredenheid en kwaliteitsverbetering. | D36: 3
A37: Stimuleert en faciliteert naast bovengenoemde competenties, ook anderen om actief klantgericht te opereren. Is in staat klantactiviteit uit te breiden d.m.v. expertise. Overtreft de verwachtingen van de klant. | D37: 4
A38: Draagt, naast bovengenoemde competenties, de verantwoordelijkheid voor een klantgerichte aanpak. Zet zich in voor het structureel hoogwaardig houden van de klantgerichtheid. | D38: 5
A40: Kennisdeling | B40: Competentieniveau tot heden | C40: Wenselijk competentieniveau | D40: Invulwaarde
A41: Neemt actief kennis op uit de DiP organisatie. | D41: 1
A42: Neemt kennis op uit de DiP organisatie en deelt actief eigen ervaringen met collega's. | D42: 2
A43: Deelt, naast bovengenoemde, actief eigen ervaringen en kennis in DiP meet-ups, peergroups en het geven van trainingen, etc. Draagt kennis eveneens extern uit in meet-ups, conferenties, trainingen, blogs, inspiratiesessies, etc. | D43: 3
A44: Is naast bovengenoemde activiteiten, door verworven kennis en ervaring een vraagbaak voor consultants in zijn/ haar specialisme. En draagt bij aan de teamspirit. | D44: 4
A45: Draagt, naast bovengenoemde activiteiten, eveneens de verantwoordelijkheid over het niveau van kennisdeling. Zorgt ervoor dat kennisdeling op peil blijft qua inhoud en frequentie. | D45: 5
A47: Coaching & begeleiding | B47: Competentieniveau tot heden | C47: Wenselijk competentieniveau | D47: Invulwaarde
...

Sheet Data (NIET BEWERKEN!!)
E1: Digital Power Basic Skills | F1: Digital Power Basic Skills | G1: Digital Power Basic Skills | H1: Digital Power Basic Skills | I1: Digital Power Basic Skills | J1: Digital Power Basic Skills | K1: Domein kennis | L1: Domein kennis | M1: Domein kennis | N1: Domein kennis | O1: Domein kennis | P1: Domein kennis | Q1: Domein kennis | R1: Domein kennis | S1: Hardskills | T1: Hardskills | U1: Hardskills | V1: Basic Consultancy Skills | W1: Basic Consultancy Skills | X1: Basic Consultancy Skills | Y1: Basic Consultancy Skills | Z1: Basic Consultancy Skills | AA1: Business Skills | AB1: Business Skills | AC1: Business Skills | AD1: Business Skills | AE1: Business Skills | AF1: Expert Consultancy Skills | AG1: Expert Consultancy Skills | AH1: Expert Consultancy Skills | AI1: Expert Consultancy Skills | AJ1: Expert Consultancy Skills
E2: Leren & reflecteren | F2: Ondersteunen & samenwerken | G2: Ondernemen & resultaatgericht | H2: Klantgericht | I2: Kennisdeling | J2: Coaching & begeleiding | K2: Datakwaliteit | L2: Data exploratie | M2: Analyse & visualisatie | N2: Modelleren | O2: Statistiek & wiskunde | P2: Domeinkennis | Q2: Deployment | R2: Ethiek & wetgeving | S2: Programmeren | T2: Engineering | U2: Machine learning | V2: Adviseren | W2: Doortastend & probleemoplossend | X2: Interpersoonlijk communicatie | Y2: Verwachtings-management | Z2: Schriftelijke en mondelinge communicatie | AA2: Organisatie- en management-identificatie | AB2: Strategische conceptualisatie | AC2: Projectmanagement | AD2: Verander-management | AE2: Leidinggeven | AF2: Situationele communicatie | AG2: Doelgerichte & effectieve communicatie | AH2: Besluitvaardigheid | AI2: Overtuigen & beinvloeden | AJ2: Opbouwende feedback & slecht nieuws gesprekken
A3: ID | B3: Naam | C3: Functie | D3: Specialisme | E3: 1 | F3: 2 | G3: 3 | H3: 4 | I3: 5 | J3: 6 | K3: 1 | L3: 2 | M3: 3 | N3: 4 | O3: 5 | P3: 6 | Q3: 7 | R3: 8 | S3: 1 | T3: 2 | U3: 3 | V3: 1 | W3: 2 | X3: 3 | Y3: 4 | Z3: 5 | AA3: 1 | AB3: 2 | AC3: 3 | AD3: 4 | AE3: 5 | AF3: 1 | AG3: 2 | AH3: 3 | AI3: 4 | AJ3: 5
A4: Huidig
A5: 1 | B5: Jijzelf (verplicht) | E5: =SUM(Vragenlijst!$B13:$B17)/COUNT(Vragenlijst!$B13:$B17) -> #DIV/0! | F5: =SUM(Vragenlijst!$B20:$B24)/COUNT(Vragenlijst!$B20:$B24) -> #DIV/0! | G5: =SUM(Vragenlijst!$B27:$B31)/COUNT(Vragenlijst!$B27:$B31) -> #DIV/0! | H5: =SUM(Vragenlijst!$B34:$B38)/COUNT(Vragenlijst!$B34:$B38) -> #DIV/0! | I5: =SUM(Vragenlijst!$B41:$B45)/COUNT(Vragenlijst!$B41:$B45) -> #DIV/0! | J5: =SUM(Vragenlijst!$B48:$B52)/COUNT(Vragenlijst!$B48:$B52) -> #DIV/0! | K5: =SUM(Vragenlijst!$B56:$B60)/COUNT(Vragenlijst!$B56:$B60) -> #DIV/0! | L5: =SUM(Vragenlijst!$B63:$B67)/COUNT(Vragenlijst!$B63:$B67) -> #DIV/0! | M5: =SUM(Vragenlijst!$B70:$B74)/COUNT(Vragenlijst!$B70:$B74) -> #DIV/0! | N5: =SUM(Vragenlijst!$B77:$B81)/COUNT(Vragenlijst!$B77:$B81) -> #DIV/0! | O5: =SUM(Vragenlijst!$B84:$B88)/COUNT(Vragenlijst!$B84:$B88) -> #DIV/0! | P5: =SUM(Vragenlijst!$B91:$B95)/COUNT(Vragenlijst!$B91:$B95) -> #DIV/0! | Q5: =SUM(Vragenlijst!$B98:$B102)/COUNT(Vragenlijst!$B98:$B102) -> #DIV/0! | R5: =SUM(Vragenlijst!$B105:$B109)/COUNT(Vragenlijst!$B105:$B109) -> #DIV/0! | S5: =SUM(Vragenlijst!$B113:$B117)/COUNT(Vragenlijst!$B113:$B117) -> #DIV/0! | T5: =SUM(Vragenlijst!$B120:$B124)/COUNT(Vragenlijst!$B120:$B124) -> #DIV/0! | U5: =SUM(Vragenlijst!$B127:$B131)/COUNT(Vragenlijst!$B127:$B131) -> #DIV/0! | V5: =SUM(Vragenlijst!$B135:$B139)/COUNT(Vragenlijst!$B135:$B139) -> #DIV/0! | W5: =SUM(Vragenlijst!$B142:$B146)/COUNT(Vragenlijst!$B142:$B146) -> #DIV/0! | X5: =SUM(Vragenlijst!$B149:$B153)/COUNT(Vragenlijst!$B149:$B153) -> #DIV/0! | Y5: =SUM(Vragenlijst!$B156:$B160)/COUNT(Vragenlijst!$B156:$B160) -> #DIV/0! | Z5: =SUM(Vragenlijst!$B163:$B167)/COUNT(Vragenlijst!$B163:$B167) -> #DIV/0! | AA5: =SUM(Vragenlijst!$B171:$B175)/COUNT(Vragenlijst!$B171:$B175) -> #DIV/0! | AB5: =SUM(Vragenlijst!$B178:$B182)/COUNT(Vragenlijst!$B178:$B182) -> #DIV/0! | AC5: =SUM(Vragenlijst!$B185:$B189)/COUNT(Vragenlijst!$B185:$B189) -> #DIV/0! | AD5: =SUM(Vragenlijst!$B192:$B196)/COUNT(Vragenlijst!$B192:$B196) -> #DIV/0! | AE5: =SUM(Vragenlijst!$B199:$B203)/COUNT(Vragenlijst!$B199:$B203) -> #DIV/0! | AF5: =SUM(Vragenlijst!$B207:$B211)/COUNT(Vragenlijst!$B207:$B211) -> #DIV/0! | AG5: =SUM(Vragenlijst!$B214:$B218)/COUNT(Vragenlijst!$B214:$B218) -> #DIV/0! | AH5: =SUM(Vragenlijst!$B221:$B225)/COUNT(Vragenlijst!$B221:$B225) -> #DIV/0! | AI5: =SUM(Vragenlijst!$B228:$B232)/COUNT(Vragenlijst!$B228:$B232) -> #DIV/0! | AJ5: =SUM(Vragenlijst!$B235:$B239)/COUNT(Vragenlijst!$B235:$B239) -> #DIV/0!
A6: 2 | B6: Feedback gever 1 (optioneel)
A7: 3 | B7: Feedback gever 2 (optioneel)
A8: 4
A9: 5
A10: 6
A11: 7
A12: 8
A13: 9
A14: 10
A16: Ambitie
A17: ID | B17: Naam | C17: Functie | D17: Specialisme | E17: 1 | F17: 2 | G17: 3 | H17: 4 | I17: 5 | J17: 6 | K17: 1 | L17: 2 | M17: 3 | N17: 4 | O17: 5 | P17: 6 | Q17: 7 | R17: 8 | S17: 1 | T17: 2 | U17: 3 | V17: 1 | W17: 2 | X17: 3 | Y17: 4 | Z17: 5 | AA17: 1 | AB17: 2 | AC17: 3 | AD17: 4 | AE17: 5 | AF17: 1 | AG17: 2 | AH17: 3 | AI17: 4 | AJ17: 5
A18: =A5 -> 1 | B18: =B5 -> Jijzelf (verplicht) | C18: =C5 -> 0 | D18: =D5 -> 0 | E18: =SUM(Vragenlijst!$C13:$C17)/COUNT(Vragenlijst!$C13:$C17) -> #DIV/0! | F18: =SUM(Vragenlijst!$C20:$C24)/COUNT(Vragenlijst!$C20:$C24) -> #DIV/0! | G18: =SUM(Vragenlijst!$C27:$C31)/COUNT(Vragenlijst!$C27:$C31) -> #DIV/0! | H18: =SUM(Vragenlijst!$C34:$C38)/COUNT(Vragenlijst!$C34:$C38) -> #DIV/0! | I18: =SUM(Vragenlijst!$C41:$C45)/COUNT(Vragenlijst!$C41:$C45) -> #DIV/0! | J18: =SUM(Vragenlijst!$C48:$C52)/COUNT(Vragenlijst!$C48:$C52) -> #DIV/0! | K18: =SUM(Vragenlijst!$C56:$C60)/COUNT(Vragenlijst!$C56:$C60) -> #DIV/0! | L18: =SUM(Vragenlijst!$C63:$C67)/COUNT(Vragenlijst!$C63:$C67) -> #DIV/0! | M18: =SUM(Vragenlijst!$C70:$C74)/COUNT(Vragenlijst!$C70:$C74) -> #DIV/0! | N18: =SUM(Vragenlijst!$C77:$C81)/COUNT(Vragenlijst!$C77:$C81) -> #DIV/0! | O18: =SUM(Vragenlijst!$C84:$C88)/COUNT(Vragenlijst!$C84:$C88) -> #DIV/0! | P18: =SUM(Vragenlijst!$C91:$C95)/COUNT(Vragenlijst!$C91:$C95) -> #DIV/0! | Q18: =SUM(Vragenlijst!$C98:$C102)/COUNT(Vragenlijst!$C98:$C102) -> #DIV/0! | R18: =SUM(Vragenlijst!$C105:$C109)/COUNT(Vragenlijst!$C105:$C109) -> #DIV/0! | S18: =SUM(Vragenlijst!$C113:$C117)/COUNT(Vragenlijst!$C113:$C117) -> #DIV/0! | T18: =SUM(Vragenlijst!$C120:$C124)/COUNT(Vragenlijst!$C120:$C124) -> #DIV/0! | U18: =SUM(Vragenlijst!$C127:$C131)/COUNT(Vragenlijst!$C127:$C131) -> #DIV/0! | V18: =SUM(Vragenlijst!$C135:$C139)/COUNT(Vragenlijst!$C135:$C139) -> #DIV/0! | W18: =SUM(Vragenlijst!$C142:$C146)/COUNT(Vragenlijst!$C142:$C146) -> #DIV/0! | X18: =SUM(Vragenlijst!$C149:$C153)/COUNT(Vragenlijst!$C149:$C153) -> #DIV/0! | Y18: =SUM(Vragenlijst!$C156:$C160)/COUNT(Vragenlijst!$C156:$C160) -> #DIV/0! | Z18: =SUM(Vragenlijst!$C163:$C167)/COUNT(Vragenlijst!$C163:$C167) -> #DIV/0! | AA18: =SUM(Vragenlijst!$C171:$C175)/COUNT(Vragenlijst!$C171:$C175) -> #DIV/0! | AB18: =SUM(Vragenlijst!$C178:$C182)/COUNT(Vragenlijst!$C178:$C182) -> #DIV/0! | AC18: =SUM(Vragenlijst!$C185:$C189)/COUNT(Vragenlijst!$C185:$C189) -> #DIV/0! | AD18: =SUM(Vragenlijst!$C192:$C196)/COUNT(Vragenlijst!$C192:$C196) -> #DIV/0! | AE18: =SUM(Vragenlijst!$C199:$C203)/COUNT(Vragenlijst!$C199:$C203) -> #DIV/0! | AF18: =SUM(Vragenlijst!$C207:$C211)/COUNT(Vragenlijst!$C207:$C211) -> #DIV/0! | AG18: =SUM(Vragenlijst!$C214:$C218)/COUNT(Vragenlijst!$C214:$C218) -> #DIV/0! | AH18: =SUM(Vragenlijst!$C221:$C225)/COUNT(Vragenlijst!$C221:$C225) -> #DIV/0! | AI18: =SUM(Vragenlijst!$C228:$C232)/COUNT(Vragenlijst!$C228:$C232) -> #DIV/0! | AJ18: =SUM(Vragenlijst!$C235:$C239)/COUNT(Vragenlijst!$C235:$C239) -> #DIV/0!
A19: =A6 -> 2 | B19: =B6 -> Feedback gever 1 (optioneel) | C19: =C6 -> 0 | D19: =D6 -> 0
A20: =A7 -> 3 | B20: =B7 -> Feedback gever 2 (optioneel) | C20: =C7 -> 0 | D20: =D7 -> 0
A21: =A8 -> 4 | B21: =B8 -> 0 | C21: =C8 -> 0 | D21: =D8 -> 0
A22: =A9 -> 5 | B22: =B9 -> 0 | C22: =C9 -> 0 | D22: =D9 -> 0
A23: =A10 -> 6 | B23: =B10 -> 0 | C23: =C10 -> 0 | D23: =D10 -> 0
A24: =A11 -> 7 | B24: =B11 -> 0 | C24: =C11 -> 0 | D24: =D11 -> 0
A25: =A12 -> 8 | B25: =B12 -> 0 | C25: =C12 -> 0 | D25: =D12 -> 0
A26: =A13 -> 9 | B26: =B13 -> 0 | C26: =C13 -> 0 | D26: =D13 -> 0
A27: =A14 -> 10 | B27: =B14 -> 0 | C27: =C14 -> 0 | D27: =D14 -> 0

Sheet Uitwerking (NIET BEWERKEN!!)
B1: ='Data (NIET BEWERKEN!!)'!E1 -> Digital Power Basic Skills | C1: ='Data (NIET BEWERKEN!!)'!F1 -> Digital Power Basic Skills | D1: ='Data (NIET BEWERKEN!!)'!G1 -> Digital Power Basic Skills | E1: ='Data (NIET BEWERKEN!!)'!H1 -> Digital Power Basic Skills | F1: ='Data (NIET BEWERKEN!!)'!I1 -> Digital Power Basic Skills | G1: ='Data (NIET BEWERKEN!!)'!J1 -> Digital Power Basic Skills | H1: ='Data (NIET BEWERKEN!!)'!K1 -> Domein kennis | I1: ='Data (NIET BEWERKEN!!)'!L1 -> Domein kennis | ... AG1: ='Data (NIET BEWERKEN!!)'!AJ1 -> Expert Consultancy Skills
B2: ='Data (NIET BEWERKEN!!)'!E2 -> Leren & reflecteren | C2: ='Data (NIET BEWERKEN!!)'!F2 -> Ondersteunen & samenwerken | D2: ='Data (NIET BEWERKEN!!)'!G2 -> Ondernemen & resultaatgericht | E2: ='Data (NIET BEWERKEN!!)'!H2 -> Klantgericht | F2: ='Data (NIET BEWERKEN!!)'!I2 -> Kennisdeling | G2: ='Data (NIET BEWERKEN!!)'!J2 -> Coaching & begeleiding | H2: ='Data (NIET BEWERKEN!!)'!K2 -> Datakwaliteit | I2: ='Data (NIET BEWERKEN!!)'!L2 -> Data exploratie | ... AG2: ='Data (NIET BEWERKEN!!)'!AJ2 -> Opbouwende feedback & slecht nieuws gesprekken
B3: 1 | C3: 2 | D3: 3 | E3: 4 | F3: 5 | G3: 6 | H3: 7 | I3: 8 | J3: 9 | K3: 10 | L3: 11 | M3: 13 | N3: 14 | O3: 15 | P3: 16 | R3: 17 | S3: 19 | T3: 20 | U3: 21 | V3: 22 | W3: 23 | X3: 25 | Y3: 26 | Z3: 27 | AA3: 28 | AB3: 29 | AC3: 30 | AD3: 31 | AE3: 32 | AF3: 33 | AG3: 34
A4: Score op huidig situatie | B4: ='Data (NIET BEWERKEN!!)'!E5 -> #DIV/0! | C4: ='Data (NIET BEWERKEN!!)'!F5 -> #DIV/0! | D4: ='Data (NIET BEWERKEN!!)'!G5 -> #DIV/0! | E4: ='Data (NIET BEWERKEN!!)'!H5 -> #DIV/0! | F4: ='Data (NIET BEWERKEN!!)'!I5 -> #DIV/0! | G4: ='Data (NIET BEWERKEN!!)'!J5 -> #DIV/0! | H4: ='Data (NIET BEWERKEN!!)'!K5 -> #DIV/0! | I4: ='Data (NIET BEWERKEN!!)'!L5 -> #DIV/0! | ... AG4: ='Data (NIET BEWERKEN!!)'!AJ5 -> #DIV/0!
A5: Totaal Gem | G5: =AVERAGE(B4:G4) -> #DIV/0! | O5: =AVERAGE(H4:R4) -> #DIV/0! | R5: =AVERAGE(P4:R4) -> #DIV/0! | W5: =AVERAGE(S4:W4) -> #DIV/0! | AB5: =AVERAGE(X4:AB4) -> #DIV/0! | AG5: =AVERAGE(AC4:AG4) -> #DIV/0!
A7: Score op ambitie | B7: ='Data (NIET BEWERKEN!!)'!E18 -> #DIV/0! | C7: ='Data (NIET BEWERKEN!!)'!F18 -> #DIV/0! | D7: ='Data (NIET BEWERKEN!!)'!G18 -> #DIV/0! | E7: ='Data (NIET BEWERKEN!!)'!H18 -> #DIV/0! | F7: ='Data (NIET BEWERKEN!!)'!I18 -> #DIV/0! | G7: ='Data (NIET BEWERKEN!!)'!J18 -> #DIV/0! | H7: ='Data (NIET BEWERKEN!!)'!K18 -> #DIV/0! | I7: ='Data (NIET BEWERKEN!!)'!L18 -> #DIV/0! | ... AG7: ='Data (NIET BEWERKEN!!)'!AJ18 -> #DIV/0!
A8: Totaal Gem | G8: =AVERAGE(B7:G7) -> #DIV/0! | O8: =AVERAGE(H7:R7) -> #DIV/0! | R8: =AVERAGE(P7:R7) -> #DIV/0! | W8: =AVERAGE(S7:W7) -> #DIV/0! | AB8: =AVERAGE(X7:AB7) -> #DIV/0! | AG8: =AVERAGE(AC7:AG7) -> #DIV/0!
