Workbook

Sheet Theorie
A2: Digital Power Competentiehuis | J2: Competentiegebieden

Sheet Vragenlijst
B1: Vragenlijst
B3: Invulinstructie
B4: Ieder competentiegebied (6), te herkennen aan de verschillende kleuren, bestaat uit een aantal specifieke competenties. Bepaal voor iedere competentie waar je ambitie (wenselijk competenieniveau) ligt en waar je nu staat (competentieniveau tot heden). - Doe dit door jezelf te scoren op de aangegeven schaal (zie voorbeeld) - Indien je (nu) geen ambitie hebt op een competentie, hou je de score aan die weergeeft wat je competentieniveau tot heden is. Bepaal bij iedere competentie welke beschrijvng het beste past voor de situatie (heden/ wens). Kijk niet alleen naar kennis en kunde, maar ook naar invloedssfeer en mate aan (persoonlijk) leiderschap in je rol bij de klant. Creeer je gewenste profiel aan de hand van je ambitie! En ontwikkel díe competenties die invulling geven aan het verwezenlijken van deze ambitie. Het doel is niet om te toetsen of je wel/ geen goede consultant bent binnen dit domein. Het doel is wel dat je competenties ontwikkelt die bij jouw ambitie passen. Wees realitisch bij het invullen. Alleen dan gebruik je het tot de volle potentie. Succes met invullen!
C24: Vul per situatie de corresponderende invulwaarde in bij de best passende competentie beschrijving | E24: Situatie competentieniveau
B25: Voorbeeld competentiegebied | C25: Competentieniveau tot heden | D25: Wenselijk competentieniveau | E25: 1 | F25: 2 | G25: 3 | H25: 4 | I25: 5
B26: Voorbeeld competentie | C26: 2 | D26: 3 | E26: Voorbeeld competentie beschrijving: Acteert bij klanten op competentie A. | F26: Voorbeeld competentie beschrijving: Acteert bij klanten naast compententie A, ook op competentie B. | G26: Voorbeeld competentie beschrijving: Acteert bij klanten naast compententie A en B, ook op competentie C. | H26: Voorbeeld competentie beschrijving: Acteert bij klanten naast compententie A, B en C, ook op competentie D. | I26: Voorbeeld competentie beschrijving: Acteert bij klanten naast compententie A, B, C en D, ook op competentie E.
B28: Digital Power basis competenties | C28: Competentieniveau tot heden | D28: Wenselijk competentieniveau | E28: 1 | F28: 2 | G28: 3 | H28: 4 | I28: 5
B29: Leren & reflecteren | E29: Heeft een groei mindset | F29: Ontvangt positieve en opbouwende feedback met een open houding, is in staat dit voor zelfreflectie te gebruiken, het op te nemen in zijn/ haar eigen ontwikkeling en hier de nodige ontwikkeling op te ondernemen met trainingen en cursussen. | G29: Is naast eerdergenoemde externe prikkel (feedback van anderen), in staat zelf kritisch te blijven op eigen kennis en ervaring en het eventueel ontbreken ervan. Neemt hierin de nodige acties en neemt daarin zelf de regie over de eigen ontwikkeling. | H29: Neemt een voorbeeldrol aan in eerdergenoemde competenties en draagt deze eveneens actief uit vanuit de begeleidende rol naar juniors en mediors. | I29: Neemt een leidersrol aan in eerdergenoemde competenties en draagt deze actief uit vanuit de begeleidersrol en/ of als organisatieverantwoordelijke.
B30: Ondersteunen & samenwerken | E30: Heeft een collegiale mindset | F30: Is behulpzaam en betrokken naar zowel interne als externe collega's | G30: Zoekt actief de samenwerking op. Zowel binnen als buiten het eigen team waarin je (tijdelijk) onderdeel van uitmaakt. | H30: Neemt een voorbeeld rol in bij het zoeken naar samenwerking. Neemt de verantwoordelijkheid op zich om anderen te ondersteunen en de hulp te bieden om ervoor te zorgen dat teamleden zelfredzaam worden in hun werkzaamheden. | I30: n.v.t.
B31: Ondernemen & resultaatgericht | E31: Heeft een ondernemende & resultaatgerichte mindset | F31: Gericht op effectief handelen en het op tijd opleveren van afgesproken werk, binnen de afgesproken tijd. | G31: Naast eerdergenoemde competenties in staat kansen te herkennen en actief te handelen om klanten te helpen en/ of DiP verder te profilen. Is in staat klantdoelstellingen te vertalen naar concrete en praktische acties. | H31: Naast eerdergenoemde competenties in staat commerciele activiteiten (zoals het uitbouwen van uren, additionele opdrachten genereren ed.) te verhogen. Ontplooit binnen DiP projecten en overziet en/ of begeleidt deze naar het beoogde resultaat. | I31: Naast eerdergenoemde competenties verantwoordelijk voor de ontwikkeling van een specialisme binnen DiP. Incl. het monitoren en marktconform houden van dit specialisme.
B32: Klantgericht | E32: Heeft een klantgerichte mindset | F32: Herkent behoeften en belangen van de klant; stelt zich hulpvaardig op en houdt in het handelen rekening met de behoeften en belangen van de klant. | G32: Denkt naast eerdergenoemde competenties, actief mee met de klant. Deelt inzichten in de klantorganisatie binnen DiP om commerciële activiteiten verder uit te kunnen breiden. Streeft daarin actief naar verhoging van klanttevredenheid en kwaliteitsverbetering. | H32: Stimuleert en faciliteert naast eerdergenoemde competenties, ook anderen om actief klantgericht te opereren. Is in staat klantactiviteit uit te breiden d.m.v. expertise. Overtreft de verwachtingen van de klant. | I32: Draagt, naast eerdergenoemde competenties, de verantwoordelijkheid voor een klantgerichte aanpak. Zet zich in voor het structureel hoogwaardig houden van de klantgerichtheid.
B33: Kennisdeling | E33: Neemt actief kennis op uit de DiP organisatie. | F33: Neemt kennis op uit de DiP organisatie en deelt actief eigen ervaringen met collega's. | G33: Deelt, naast eerdergenoemde, actief eigen ervaringen en kennis in DiP meet-ups, peergroups en het geven van trainingen, etc. Draagt kennis eveneens extern uit in meet-ups, conferenties, trainingen, blogs, inspiratiesessies, etc. | H33: Is naast eerdergenoemde activiteiten, door verworven kennis en ervaring een vraagbaak voor consultants in zijn/ haar specialisme. En draagt bij aan de teamspirit. | I33: Draagt, naast eerdergenoemde activiteiten, eveneens de verantwoordelijkheid over het niveau van kennisdeling. Zorgt ervoor dat kennisdeling op peil blijft qua inhoud en frequentie.
B34: Coaching & begeleiding | E34: Heeft nooit (in)formeel coaching of begeleiding gegeven op professioneel gebied | F34: Heeft één of meerdere trainingen/ cursussen gevolgd over coachen en/ of begeleiden op professioneel gebied. | G34: Heeft (binnen DiP) één of meerdere collega's informeel gecoached en/ of begeleidt op professioneel gebied. | H34: Begeleidt (binnen DiP) formeel één of meerdere junior/ medior consultants op professioneel gebied in hun ontwikkeling. | I34: Begeleidt (binnen DiP) formeel meer dan 4 jaar één of meerdere junior/ medior/ senior consultants op professioeel gebied in hun ontwikkeling.
B36: Ethiek en professionaliteit | C36: Competentieniveau tot heden | D36: Wenselijk competentieniveau | E36: 0. Onbekend mee (ken het niet) 1. Bekend mee (ik weet wat het kan) 2. Hobbymatig (Mee gewerkt) 3. Acceptabel (kan erop verkocht worden) 4. Marktconform / Prima (vergelijkbaar binnen DiP en buiten DiP) 5. Beter dan marktconform 6. Onderscheidend (onderscheidend binnen DiP en buiten DiP) Kun je onderscheidend zijn op assumpties? of bijv. correlatie?
B37: Is zich bewust van het bestaan van de AVG en andere relevante wetgeving
B38: Is bekend met de juridische eisen rondom privacy (AVG, data opslag, dataverzameling, datalek, etc) en neemt deze in acht bij de eigen werkzaamheden.
B39: Adviseert klanten pro-actief over de juridische eisen en implicaties rondom privacy.
B40: Neemt naast bovengenoemde, eveneens ethische overwegingen en implicaties in acht bij de eigen werkzaamheden. Attendeert over dit aspect.
B41: Adviseert klanten pro-actief over de ethische overwegingen en implicaties van keuzes.
B43: Basis Data vaardigheden | C43: Competentieniveau tot heden | D43: Wenselijk competentieniveau | E43: 0. Onbekend mee (ken het niet) 1. Bekend mee (ik weet wat het kan) 2. Hobbymatig (Mee gewerkt) 3. Acceptabel (kan erop verkocht worden) 4. Marktconform / Prima (vergelijkbaar binnen DiP en buiten DiP) 5. Beter dan marktconform 6. Onderscheidend (onderscheidend binnen DiP en buiten DiP) Kun je onderscheidend zijn op assumpties? of bijv. correlatie?
B44: Is bewust van de verschillende typen data en de (on)mogelijkheden hiervan Met typen data wordt nominaal, ordinaal interval en ratio bedoeld.
B45: Begrijpt data kwaliteit en herkent problemen hierin Bekend met verschillende problemen en biases die in data voorkomen. Te denken aan onvolledig, onjuist, inconsistent en/of verouderd.
B46: Kent ook de oplossingen om met data kwaliteitsproblemen om te gaan Kan passende oplossingen toepassen voor verschillende data kwaliteitsproblemen.
B47: Kan doelmatig en doeltreffend data bewerken/manipuleren Data bewerken en combineren ter voorbereiding van het analyseren. Van handmatig in Excel tot formules t/m script.
B49: Statistiek | C49: Competentieniveau tot heden | D49: Wenselijk competentieniveau | E49: 0. Onbekend mee (ken het niet) 1. Bekend mee (ik weet wat het kan) 2. Hobbymatig (Mee gewerkt) 3. Acceptabel (kan erop verkocht worden) 4. Marktconform / Prima (vergelijkbaar binnen DiP en buiten DiP) 5. Beter dan marktconform 6. Onderscheidend (onderscheidend binnen DiP en buiten DiP) Kun je onderscheidend zijn op assumpties? of bijv. correlatie?
B50: Assumpties steekproefgrootte, verdeling e.d. De assumpties/aannames die worden gehanteerd voor het bepalen van de statistische toets. Het checken van de verdeling a.d.h.v. beschrijvende statistieken zoals standaard deviatie, modus, mediaan e.d.
B51: Betrouwbaarsheids intervallen Met betrouwbaarheids intervallen wordt bedoeld de interval van waarden waartussen het resultaat van je onderzoek/steefproef valt.
B52: Statistische toetsen - wanneer welke toepassen? De verschillende toetsen zoals z-test, t-test, chi-kwadraattoets die worden toegepast bij het analyseren van een experiment
B53: Correlatie Meeteenheid om statisch verband aan te tonen.
B54: Regressie Meetmethode om a.d.h.v. verschillende variabelen verband en voorspellende waarde aan te tonen
B56: Kwalitatieve Analyse en Onderzoeksvaardigheden | C56: Competentieniveau tot heden | D56: Wenselijk competentieniveau | E56: 0. Onbekend mee (ken het niet) 1. Bekend mee (ik weet wat het kan) 2. Hobbymatig (Mee gewerkt) 3. Acceptabel (kan erop verkocht worden) 4. Marktconform / Prima (vergelijkbaar binnen DiP en buiten DiP) 5. Beter dan marktconform 6. Onderscheidend (onderscheidend binnen DiP en buiten DiP) Kun je onderscheidend zijn op assumpties? of bijv. correlatie?
B57: Betrouwbaarheid & Validiteit Bekend met de begrippen, kan onderzoeken hierop beoordelen.
B58: Selecteren passende onderzoekmethode voor vraagstuk In staat om de juiste onderzoeksmethode te selecteren voor het vraagstuk en doel.
B59: Onderzoeksdesign Kan een onderzoeksontwerp maken voor het realiseren van het onderzoek met betrekking op validiteit en betrouwbaarheid en haalbaarheid & ethiek.
B60: Interpreteren van onderzoeksresultaten naar waarde Herkennen van wat de onderzoeksresultaten betekenen voor de organisatie en de acties die eruit kunnen komen.
B61: Onderzoeksvaardigheden in business context In staat om de juiste onderzoeksmethode te selecteren voor het vraagstuk in relatie tot de business context met betrekking op kosten, tijd tot resultaten en verschillende stakeholder belangen.
B63: Metrics en doelen | C63: Competentieniveau tot heden | D63: Wenselijk competentieniveau | E63: 0. Onbekend mee (ken het niet) 1. Bekend mee (ik weet wat het kan) 2. Hobbymatig (Mee gewerkt) 3. Acceptabel (kan erop verkocht worden) 4. Marktconform / Prima (vergelijkbaar binnen DiP en buiten DiP) 5. Beter dan marktconform 6. Onderscheidend (onderscheidend binnen DiP en buiten DiP) Kun je onderscheidend zijn op assumpties? of bijv. correlatie?
B64: Metrics voor de usability- en user experience De vertaling van menselijk gedrag naar metrics op gedrag en attitude niveau. Te denken aan time on task, task succes rate en satisfaction.
B65: Metrics voor de customer experience De vertaling van de klantervaring naar meeteenheden zoals CSAT, NPS of CES
B66: Metrics aansluiting maken tussen de strategie en ux/cx metrics Gelaagdheid in metrics aanbrengen op elk niveau(individueel, operationeel, tactisch, strategisch) in de organisatie. Zijn de metrics de drivers van de strategie?
...

Sheet Data (NIET BEWERKEN!!)
E2: Digital Power Basic Skills | F2: Digital Power Basic Skills | G2: Digital Power Basic Skills | H2: Digital Power Basic Skills | I2: Digital Power Basic Skills | J2: Digital Power Basic Skills | K2: Domein Skills | L2: Domein Skills | M2: Domein Skills | N2: Domein Skills | O2: Domein Skills | P2: Domein Skills | Q2: Domein Skills | R2: Domein Skills | S2: Domein Skills | T2: Domein Skills | U2: Domein Skills | V2: Domein Skills | W2: Domein Skills | X2: Domein Skills | Y2: Domein Skills | Z2: Domein Skills | AA2: Domein Skills | AB2: Domein Skills | AC2: Domein Skills | AD2: Domein Skills | AE2: Domein Skills | AF2: Domein Skills | AG2: Domein Skills | AH2: Domein Skills | AI2: Domein Skills | AJ2: Domein Skills | AK2: Domein Skills | AL2: Domein Skills | AM2: Domein Skills | AN2: Domein Skills | AO2: Domein Skills | AP2: Domein Skills | AQ2: Domein Skills | AR2: Domein Skills | AS2: Domein Skills | AT2: Domein Skills | AU2: Domein Skills | AV2: Domein Skills | AW2: Domein Skills | AX2: Domein Skills | AY2: Hardskills | AZ2: Hardskills | BA2: Hardskills | BB2: Hardskills | BC2: Hardskills | BD2: Hardskills | BE2: Hardskills | BF2: Hardskills | BG2: Hardskills | BH2: Hardskills | BI2: Hardskills | BJ2: Hardskills | BK2: Hardskills | BL2: Hardskills | BM2: Hardskills | BN2: Basic Consultancy Skills | BO2: Basic Consultancy Skills | BP2: Basic Consultancy Skills | BQ2: Basic Consultancy Skills | BR2: Basic Consultancy Skills | BS2: Business Skills | BT2: Business Skills | BU2: Business Skills | BV2: Business Skills | BW2: Business Skills | BX2: Expert Consultancy Skills | BY2: Expert Consultancy Skills | BZ2: Expert Consultancy Skills | CA2: Expert Consultancy Skills | CB2: Expert Consultancy Skills
K3: =Vragenlijst!$B36 -> Ethiek en professionaliteit | L3: =Vragenlijst!$B36 -> Ethiek en professionaliteit | M3: =Vragenlijst!$B36 -> Ethiek en professionaliteit | N3: =Vragenlijst!$B36 -> Ethiek en professionaliteit | O3: =Vragenlijst!$B36 -> Ethiek en professionaliteit | P3: =Vragenlijst!$B43 -> Basis Data vaardigheden | Q3: =Vragenlijst!$B43 -> Basis Data vaardigheden | R3: =Vragenlijst!$B43 -> Basis Data vaardigheden | S3: =Vragenlijst!$B43 -> Basis Data vaardigheden | T3: =Vragenlijst!$B49 -> Statistiek | U3: =Vragenlijst!$B49 -> Statistiek | V3: =Vragenlijst!$B49 -> Statistiek | W3: =Vragenlijst!$B49 -> Statistiek | X3: =Vragenlijst!$B49 -> Statistiek | Y3: =Vragenlijst!$B56 -> Kwalitatieve Analyse en Onderzoeksvaardigheden | Z3: =Vragenlijst!$B56 -> Kwalitatieve Analyse en Onderzoeksvaardigheden | AA3: =Vragenlijst!$B56 -> Kwalitatieve Analyse en Onderzoeksvaardigheden | AB3: =Vragenlijst!$B56 -> Kwalitatieve Analyse en Onderzoeksvaardigheden | AC3: =Vragenlijst!$B56 -> Kwalitatieve Analyse en Onderzoeksvaardigheden | AD3: =Vragenlijst!$B63 -> Metrics en doelen | AE3: =Vragenlijst!$B63 -> Metrics en doelen | AF3: =Vragenlijst!$B63 -> Metrics en doelen | AG3: =Vragenlijst!$B63 -> Metrics en doelen | AH3: =Vragenlijst!$B63 -> Metrics en doelen | AI3: =Vragenlijst!$B70 -> CX Theorie | AJ3: =Vragenlijst!$B70 -> CX Theorie | AK3: =Vragenlijst!$B70 -> CX Theorie | AL3: =Vragenlijst!$B70 -> CX Theorie | AM3: =Vragenlijst!$B70 -> CX Theorie | AN3: =Vragenlijst!$B70 -> CX Theorie | AO3: =Vragenlijst!$B70 -> CX Theorie | AP3: =Vragenlijst!$B70 -> CX Theorie | AQ3: =Vragenlijst!$B80 -> CX Kennis toepassingsdomein | AR3: =Vragenlijst!$B80 -> CX Kennis toepassingsdomein | AS3: =Vragenlijst!$B80 -> CX Kennis toepassingsdomein | AT3: =Vragenlijst!$B80 -> CX Kennis toepassingsdomein | AU3: =Vragenlijst!$B80 -> CX Kennis toepassingsdomein | AV3: =Vragenlijst!$B87 -> Bonusskill | AW3: =Vragenlijst!$B87 -> Bonusskill | AX3: =Vragenlijst!$B87 -> Bonusskill
E4: Leren & reflecteren | F4: Ondersteunen & samenwerken | G4: Ondernemen & resultaatgericht | H4: Klantgericht | I4: Kennisdeling | J4: Coaching & begeleiding | K4: Bewust | L4: Bekend | M4: Adviseert | N4: Neemt mee in werkzaamheden | O4: Adviseert pro-actief | P4: Bewust van verschillende typen data en de (on)mogelijkheden | Q4: Begrijpt data kwaliteit en herkent problemen | R4: Kent oplossingen om data met kwaliteitsproblemen om te gaan | S4: Kan doelmatig en doeltreffend data bewerken/ manipuleren | T4: Assumpties steekproefgrootte, verdeling, etc. | U4: Betrouwbaarheids intervallen | V4: Statistische toetsen | W4: Correlatie | X4: Regressie | Y4: betrouwbaarheid & validiteit | Z4: Selecteren onderzoeksmethode | AA4: Onderzoeksdesign | AB4: Interpreteren onderzoeksresultaten | AC4: Onderzoeksvaardigheden in business | AD4: Metrics voor usability en UX | AE4: Metrics voor CX | AF4: Metrics aansluiting tussen strategie en ux/ cx metrics | AG4: Metrics vertalen naar meetbare definities | AH4: Metrics op het juiste organisatie niveau | AI4: Perceptie en decisionmaking | AJ4: Kunnen inzetten van DiP optmalisatieproces | AK4: CX Marurty modellen | AL4: Merk, usability, UX en CX | AM4: CX strategie | AN4: Copywriting | UX writing | Content | AO4: Custoner Journer Mapping & Persona's | AP4: Personalisatie en segmentatie | AQ4: Customer Journey (CXO) | AR4: Marketing Analytics | AS4: eCommerce Analytics | AT4: Product Analytics | AU4: Customer Service Optimalisatie | AV4: Design | AW4: Prototyping | AX4: Visual design | AY4: =Vragenlijst!K93 -> Customer Journey Mapping | AZ4: =Vragenlijst!K94 -> Usability Testen - Formative | BA4: =Vragenlijst!K95 -> Usability Testen - Summative | BB4: =Vragenlijst!K96 -> AB Testen | BC4: =Vragenlijst!K97 -> Behavioral Analytics (Web en app analytics tooling) | BD4: =Vragenlijst!K98 -> Marketing Analytics | BE4: =Vragenlijst!K99 -> Session recordings | BF4: =Vragenlijst!K100 -> Heathmaps & Scrollmaps | BG4: =Vragenlijst!K101 -> Interviewen (opzetten en uitvoeren van een interview) | BH4: =Vragenlijst!K102 -> Survey Design (opzetten en uitvoeren van een survey) | BI4: =Vragenlijst!K103 -> SQL | BJ4: =Vragenlijst!K104 -> Python | BK4: =Vragenlijst!K105 -> Javascript | BL4: =Vragenlijst!K106 -> R | BM4: =Vragenlijst!K107 -> HTML / CSS | BN4: Adviseren | BO4: Doortastend & probleemoplossend | BP4: Interpersoonlijk communicatie | BQ4: Verwachtings-management | BR4: Schriftelijke en mondelinge communicatie | BS4: Organisatie- en management-identificatie | BT4: Strategische conceptualisatie | BU4: Projectmanagement | BV4: Verander-management | BW4: Leidinggeven | BX4: Situationele communicatie | BY4: Doelgerichte & effectieve communicatie | BZ4: Besluitvaardigheid | CA4: Overtuigen & beinvloeden | CB4: Opbouwende feedback & slecht nieuws gesprekken
A5: ID | B5: Naam | C5: Functie | D5: Specialisme | E5: 1 | F5: 2 | G5: 3 | H5: 4 | I5: 5 | J5: 6 | K5: 1 | L5: =K5+1 -> 2 | M5: =L5+1 -> 3 | N5: =M5+1 -> 4 | O5: =N5+1 -> 5 | P5: 1 | Q5: 2 | R5: 3 | S5: 4 | T5: 1 | U5: 2 | V5: 3 | W5: 4 | X5: 5 | Y5: 1 | Z5: 2 | AA5: 3 | AB5: 4 | AC5: 5 | AD5: 1 | AE5: 2 | AF5: 3 | AG5: 4 | AH5: 5 | AI5: 1 | AJ5: 2 | AK5: 3 | AL5: 4 | AM5: 5 | AN5: =AM5+1 -> 6 | AO5: =AN5+1 -> 7 | AP5: =AO5+1 -> 8 | AQ5: 1 | AR5: =AQ5+1 -> 2 | AS5: =AR5+1 -> 3 | AT5: =AS5+1 -> 4 | AU5: =AT5+1 -> 5 | AV5: 1 | AW5: =AV5+1 -> 2 | AX5: =AW5+1 -> 3 | AY5: =Vragenlijst!A93 -> 1 | AZ5: =Vragenlijst!A94 -> 2 | BA5: =Vragenlijst!A95 -> 3 | BB5: =Vragenlijst!A96 -> 4 | BC5: 5 | BD5: 6 | BE5: 7 | BF5: 8 | BG5: 9 | BH5: 10 | BI5: 11 | BJ5: 12 | BK5: 13 | BL5: 14 | BM5: 15 | BN5: 1 | BO5: 2 | BP5: 3 | BQ5: 4 | BR5: 5 | BS5: 1 | BT5: 2 | BU5: 3 | BV5: 4 | BW5: 5 | BX5: 1 | BY5: 2 | BZ5: 3 | CA5: 4 | CB5: 5
A6: Huidig
A7: 1 | B7: Jijzelf (verplicht) | E7: =Vragenlijst!C29 -> 0 | F7: =Vragenlijst!C30 -> 0 | G7: =Vragenlijst!C31 -> 0 | H7: =Vragenlijst!C32 -> 0 | I7: =Vragenlijst!C33 -> 0 | J7: =Vragenlijst!C34 -> 0 | K7: =Vragenlijst!C37 -> 0 | L7: =Vragenlijst!C38 -> 0 | M7: =Vragenlijst!C39 -> 0 | N7: =Vragenlijst!C40 -> 0 | O7: =Vragenlijst!C41 -> 0 | P7: =Vragenlijst!C44 -> 0 | Q7: =Vragenlijst!C45 -> 0 | R7: =Vragenlijst!C46 -> 0 | S7: =Vragenlijst!C47 -> 0 | T7: =Vragenlijst!C50 -> 0 | U7: =Vragenlijst!C51 -> 0 | V7: =Vragenlijst!C52 -> 0 | W7: =Vragenlijst!C53 -> 0 | X7: =Vragenlijst!C54 -> 0 | Y7: =Vragenlijst!C57 -> 0 | Z7: =Vragenlijst!C58 -> 0 | AA7: =Vragenlijst!C59 -> 0 | AB7: =Vragenlijst!C60 -> 0 | AC7: =Vragenlijst!C61 -> 0 | AD7: =Vragenlijst!C64 -> 0 | AE7: =Vragenlijst!C65 -> 0 | AF7: =Vragenlijst!C66 -> 0 | AG7: =Vragenlijst!C67 -> 0 | AH7: =Vragenlijst!C68 -> 0 | AI7: =Vragenlijst!C71 -> 0 | AJ7: =Vragenlijst!C72 -> 0 | AK7: =Vragenlijst!C73 -> 0 | AL7: =Vragenlijst!C74 -> 0 | AM7: =Vragenlijst!C75 -> 0 | AN7: =Vragenlijst!C76 -> 0 | AO7: =Vragenlijst!C77 -> 0 | AP7: =Vragenlijst!C78 -> 0 | AQ7: =Vragenlijst!C81 -> 0 | AR7: =Vragenlijst!C82 -> 0 | AS7: =Vragenlijst!C83 -> 0 | AT7: =Vragenlijst!C84 -> 0 | AU7: =Vragenlijst!C85 -> 0 | AV7: =Vragenlijst!C88 -> 0 | AW7: =Vragenlijst!C89 -> 0 | AX7: =Vragenlijst!C90 -> 0 | AY7: =Vragenlijst!C93 -> 0 | AZ7: =Vragenlijst!C94 -> 0 | BA7: =Vragenlijst!C95 -> 0 | BB7: =Vragenlijst!C96 -> 0 | BC7: =Vragenlijst!C97 -> 0 | BD7: =Vragenlijst!C98 -> 0 | BE7: =Vragenlijst!C99 -> 0 | BF7: =Vragenlijst!C100 -> 0 | BG7: =Vragenlijst!C101 -> 0 | BH7: =Vragenlijst!C102 -> 0 | BI7: =Vragenlijst!C103 -> 0 | BJ7: =Vragenlijst!C104 -> 0 | BK7: =Vragenlijst!C105 -> 0 | BL7: =Vragenlijst!C106 -> 0 | BM7: =Vragenlijst!C107 -> 0 | BN7: =Vragenlijst!C110 -> 0 | BO7: =Vragenlijst!C111 -> 0 | BP7: =Vragenlijst!C112 -> 0 | BQ7: =Vragenlijst!C113 -> 0 | BR7: =Vragenlijst!C114 -> 0 | BS7: =Vragenlijst!C117 -> 0 | BT7: =Vragenlijst!C118 -> 0 | BU7: =Vragenlijst!C119 -> 0 | BV7: =Vragenlijst!C120 -> 0 | BW7: =Vragenlijst!C121 -> 0 | BX7: =Vragenlijst!C124 -> 0 | BY7: =Vragenlijst!C125 -> 0 | BZ7: =Vragenlijst!C126 -> 0 | CA7: =Vragenlijst!C127 -> 0 | CB7: =Vragenlijst!C128 -> 0
A8: 2 | B8: Feedback gever 1 (optioneel)
A9: 3 | B9: Feedback gever 2 (optioneel)
A10: 4
A11: 5
A12: 6
A13: 7
A14: 8
A15: 9
A16: 10
A18: Ambitie
A19: ID | B19: Naam | C19: Functie | D19: Specialisme | E19: =E5 -> 1 | F19: =F5 -> 2 | G19: =G5 -> 3 | H19: =H5 -> 4 | I19: =I5 -> 5 | J19: =J5 -> 6 | K19: =K5 -> 1 | L19: =L5 -> 2 | ... CB19: =CB5 -> 5
A20: =A7 -> 1 | B20: =B7 -> Jijzelf (verplicht) | C20: =C7 -> 0 | D20: =D7 -> 0 | E20: =Vragenlijst!D29 -> 0 | F20: =Vragenlijst!D30 -> 0 | G20: =Vragenlijst!D31 -> 0 | H20: =Vragenlijst!D32 -> 0 | I20: =Vragenlijst!D33 -> 0 | J20: =Vragenlijst!D34 -> 0 | K20: =Vragenlijst!D37 -> 0 | L20: =Vragenlijst!D38 -> 0 | M20: =Vragenlijst!D39 -> 0 | N20: =Vragenlijst!D40 -> 0 | O20: =Vragenlijst!D41 -> 0 | P20: =Vragenlijst!D44 -> 0 | Q20: =Vragenlijst!D45 -> 0 | R20: =Vragenlijst!D46 -> 0 | S20: =Vragenlijst!D47 -> 0 | T20: =Vragenlijst!D50 -> 0 | U20: =Vragenlijst!D51 -> 0 | V20: =Vragenlijst!D52 -> 0 | W20: =Vragenlijst!D53 -> 0 | X20: =Vragenlijst!D54 -> 0 | Y20: =Vragenlijst!D57 -> 0 | Z20: =Vragenlijst!D58 -> 0 | AA20: =Vragenlijst!D59 -> 0 | AB20: =Vragenlijst!D60 -> 0 | AC20: =Vragenlijst!D61 -> 0 | AD20: =Vragenlijst!D64 -> 0 | AE20: =Vragenlijst!D65 -> 0 | AF20: =Vragenlijst!D66 -> 0 | AG20: =Vragenlijst!D67 -> 0 | AH20: =Vragenlijst!D68 -> 0 | AI20: =Vragenlijst!D71 -> 0 | AJ20: =Vragenlijst!D72 -> 0 | AK20: =Vragenlijst!D73 -> 0 | AL20: =Vragenlijst!D74 -> 0 | AM20: =Vragenlijst!D75 -> 0 | AN20: =Vragenlijst!D76 -> 0 | AO20: =Vragenlijst!D77 -> 0 | AP20: =Vragenlijst!D78 -> 0 | AQ20: =Vragenlijst!D81 -> 0 | AR20: =Vragenlijst!D82 -> 0 | AS20: =Vragenlijst!D83 -> 0 | AT20: =Vragenlijst!D84 -> 0 | AU20: =Vragenlijst!D85 -> 0 | AV20: =Vragenlijst!D88 -> 0 | AW20: =Vragenlijst!D89 -> 0 | AX20: =Vragenlijst!D90 -> 0 | AY20: =Vragenlijst!D93 -> 0 | AZ20: =Vragenlijst!D94 -> 0 | BA20: =Vragenlijst!D95 -> 0 | BB20: =Vragenlijst!D96 -> 0 | BC20: =Vragenlijst!D97 -> 0 | BD20: =Vragenlijst!D98 -> 0 | BE20: =Vragenlijst!D99 -> 0 | BF20: =Vragenlijst!D100 -> 0 | BG20: =Vragenlijst!D101 -> 0 | BH20: =Vragenlijst!D102 -> 0 | BI20: =Vragenlijst!D103 -> 0 | BJ20: =Vragenlijst!D104 -> 0 | BK20: =Vragenlijst!D105 -> 0 | BL20: =Vragenlijst!D106 -> 0 | BM20: =Vragenlijst!D107 -> 0 | BN20: =Vragenlijst!D110 -> 0 | BO20: =Vragenlijst!D111 -> 0 | BP20: =Vragenlijst!D112 -> 0 | BQ20: =Vragenlijst!D113 -> 0 | BR20: =Vragenlijst!D114 -> 0 | BS20: =Vragenlijst!D117 -> 0 | BT20: =Vragenlijst!D118 -> 0 | BU20: =Vragenlijst!D119 -> 0 | BV20: =Vragenlijst!D120 -> 0 | BW20: =Vragenlijst!D121 -> 0 | BX20: =Vragenlijst!D124 -> 0 | BY20: =Vragenlijst!D125 -> 0 | BZ20: =Vragenlijst!D126 -> 0 | CA20: =Vragenlijst!D127 -> 0 | CB20: =Vragenlijst!D128 -> 0
A21: =A8 -> 2 | B21: =B8 -> Feedback gever 1 (optioneel) | C21: =C8 -> 0 | D21: =D8 -> 0
A22: =A9 -> 3 | B22: =B9 -> Feedback gever 2 (optioneel) | C22: =C9 -> 0 | D22: =D9 -> 0
A23: =A10 -> 4 | B23: =B10 -> 0 | C23: =C10 -> 0 | D23: =D10 -> 0
A24: =A11 -> 5 | B24: =B11 -> 0 | C24: =C11 -> 0 | D24: =D11 -> 0
A25: =A12 -> 6 | B25: =B12 -> 0 | C25: =C12 -> 0 | D25: =D12 -> 0
A26: =A13 -> 7 | B26: =B13 -> 0 | C26: =C13 -> 0 | D26: =D13 -> 0
A27: =A14 -> 8 | B27: =B14 -> 0 | C27: =C14 -> 0 | D27: =D14 -> 0
A28: =A15 -> 9 | B28: =B15 -> 0 | C28: =C15 -> 0 | D28: =D15 -> 0
A29: =A16 -> 10 | B29: =B16 -> 0 | C29: =C16 -> 0 | D29: =D16 -> 0
D32: Competentie omschrijving | E32: =CONCATENATE("=Vragenlijst!B",E1) -> =Vragenlijst!B | F32: =CONCATENATE("=Vragenlijst!B",F1) -> =Vragenlijst!B | G32: =CONCATENATE("=Vragenlijst!B",G1) -> =Vragenlijst!B | H32: =CONCATENATE("=Vragenlijst!B",H1) -> =Vragenlijst!B | I32: =CONCATENATE("=Vragenlijst!B",I1) -> =Vragenlijst!B | J32: =CONCATENATE("=Vragenlijst!B",J1) -> =Vragenlijst!B | K32: =CONCATENATE("=Vragenlijst!B",K1) -> =Vragenlijst!B | N32: =CONCATENATE("=Vragenlijst!B",N1) -> =Vragenlijst!B | O32: =CONCATENATE("=Vragenlijst!B",O1) -> =Vragenlijst!B | P32: =CONCATENATE("=Vragenlijst!B",P1) -> =Vragenlijst!B | Q32: =CONCATENATE("=Vragenlijst!B",Q1) -> =Vragenlijst!B | R32: =CONCATENATE("=Vragenlijst!B",R1) -> =Vragenlijst!B | S32: =CONCATENATE("=Vragenlijst!B",S1) -> =Vragenlijst!B | T32: =CONCATENATE("=Vragenlijst!B",T1) -> =Vragenlijst!B | U32: =CONCATENATE("=Vragenlijst!B",U1) -> =Vragenlijst!B | ... AX32: =CONCATENATE("=Vragenlijst!B",AX1) -> =Vragenlijst!B | AY32: =CONCATENATE("=Vragenlijst!K",AY1) -> =Vragenlijst!K | AZ32: =CONCATENATE("=Vragenlijst!K",AZ1) -> =Vragenlijst!K | BA32: =CONCATENATE("=Vragenlijst!K",BA1) -> =Vragenlijst!K | BB32: =CONCATENATE("=Vragenlijst!K",BB1) -> =Vragenlijst!K | BC32: =CONCATENATE("=Vragenlijst!K",BC1) -> =Vragenlijst!K | BD32: =CONCATENATE("=Vragenlijst!K",BD1) -> =Vragenlijst!K | BE32: =CONCATENATE("=Vragenlijst!K",BE1) -> =Vragenlijst!K | BF32: =CONCATENATE("=Vragenlijst!K",BF1) -> =Vragenlijst!K | ... BM32: =CONCATENATE("=Vragenlijst!K",BM1) -> =Vragenlijst!K
D34: Huig | E34: =CONCATENATE("=Vragenlijst!C",E1) -> =Vragenlijst!C | F34: =CONCATENATE("=Vragenlijst!C",F1) -> =Vragenlijst!C | G34: =CONCATENATE("=Vragenlijst!C",G1) -> =Vragenlijst!C | H34: =CONCATENATE("=Vragenlijst!C",H1) -> =Vragenlijst!C | I34: =CONCATENATE("=Vragenlijst!C",I1) -> =Vragenlijst!C | J34: =CONCATENATE("=Vragenlijst!C",J1) -> =Vragenlijst!C | K34: =CONCATENATE("=Vragenlijst!C",K1) -> =Vragenlijst!C | L34: =CONCATENATE("=Vragenlijst!C",L1) -> =Vragenlijst!C | ... CB34: =CONCATENATE("=Vragenlijst!C",CB1) -> =Vragenlijst!C
D36: Ambitie | E36: =CONCATENATE("=Vragenlijst!D",E1) -> =Vragenlijst!D | F36: =CONCATENATE("=Vragenlijst!D",F1) -> =Vragenlijst!D | G36: =CONCATENATE("=Vragenlijst!D",G1) -> =Vragenlijst!D | H36: =CONCATENATE("=Vragenlijst!D",H1) -> =Vragenlijst!D | I36: =CONCATENATE("=Vragenlijst!D",I1) -> =Vragenlijst!D | J36: =CONCATENATE("=Vragenlijst!D",J1) -> =Vragenlijst!D | K36: =CONCATENATE("=Vragenlijst!D",K1) -> =Vragenlijst!D | L36: =CONCATENATE("=Vragenlijst!D",L1) -> =Vragenlijst!D | ... CB36: =CONCATENATE("=Vragenlijst!D",CB1) -> =Vragenlijst!D

Sheet Uitwerking (NIET BEWERKEN!!)
E2: ='Data (NIET BEWERKEN!!)'!E2 -> Digital Power Basic Skills | F2: ='Data (NIET BEWERKEN!!)'!F2 -> Digital Power Basic Skills | G2: ='Data (NIET BEWERKEN!!)'!G2 -> Digital Power Basic Skills | H2: ='Data (NIET BEWERKEN!!)'!H2 -> Digital Power Basic Skills | I2: ='Data (NIET BEWERKEN!!)'!I2 -> Digital Power Basic Skills | J2: ='Data (NIET BEWERKEN!!)'!J2 -> Digital Power Basic Skills | K2: ='Data (NIET BEWERKEN!!)'!K2 -> Domein Skills | L2: ='Data (NIET BEWERKEN!!)'!L2 -> Domein Skills | ... CB2: ='Data (NIET BEWERKEN!!)'!CB2 -> Expert Consultancy Skills
K3: Ethiek en professionaliteit | L3: Ethiek en professionaliteit | M3: Ethiek en professionaliteit | N3: Ethiek en professionaliteit | O3: Ethiek en professionaliteit | P3: Basis data vaardigheden | Q3: Basis data vaardigheden | R3: Basis data vaardigheden | S3: Basis data vaardigheden | T3: Statistiek | U3: Statistiek | V3: Statistiek | W3: Statistiek | X3: Statistiek | Y3: Kwantitatieve Analyse en Onderzoeksvaardigheden | Z3: Kwantitatieve Analyse en Onderzoeksvaardigheden | AA3: Kwantitatieve Analyse en Onderzoeksvaardigheden | AB3: Kwantitatieve Analyse en Onderzoeksvaardigheden | AC3: Kwantitatieve Analyse en Onderzoeksvaardigheden | AD3: Metrics en doelen | AE3: Metrics en doelen | AF3: Metrics en doelen | AG3: Metrics en doelen | AH3: Metrics en doelen | AI3: CX Theorie | AJ3: CX Theorie | AK3: CX Theorie | AL3: CX Theorie | AM3: CX Theorie | AN3: CX Theorie | AO3: CX Theorie | AP3: CX Theorie | AQ3: CX Kennis toepassingsdomein | AR3: CX Kennis toepassingsdomein | AS3: CX Kennis toepassingsdomein | AT3: CX Kennis toepassingsdomein | AU3: CX Kennis toepassingsdomein | AV3: Bonusskill | AW3: Bonusskill | AX3: Bonusskill
E4: ='Data (NIET BEWERKEN!!)'!E4 -> Leren & reflecteren | F4: ='Data (NIET BEWERKEN!!)'!F4 -> Ondersteunen & samenwerken | G4: ='Data (NIET BEWERKEN!!)'!G4 -> Ondernemen & resultaatgericht | H4: ='Data (NIET BEWERKEN!!)'!H4 -> Klantgericht | I4: ='Data (NIET BEWERKEN!!)'!I4 -> Kennisdeling | J4: ='Data (NIET BEWERKEN!!)'!J4 -> Coaching & begeleiding | K4: ='Data (NIET BEWERKEN!!)'!K4 -> Bewust | L4: ='Data (NIET BEWERKEN!!)'!L4 -> Bekend | ... CB4: ='Data (NIET BEWERKEN!!)'!CB4 -> Opbouwende feedback & slecht nieuws gesprekken
E5: ='Data (NIET BEWERKEN!!)'!E5 -> 1 | F5: ='Data (NIET BEWERKEN!!)'!F5 -> 2 | G5: ='Data (NIET BEWERKEN!!)'!G5 -> 3 | H5: ='Data (NIET BEWERKEN!!)'!H5 -> 4 | I5: ='Data (NIET BEWERKEN!!)'!I5 -> 5 | J5: ='Data (NIET BEWERKEN!!)'!J5 -> 6 | K5: ='Data (NIET BEWERKEN!!)'!K5 -> 1 | L5: ='Data (NIET BEWERKEN!!)'!L5 -> 2 | ... CB5: ='Data (NIET BEWERKEN!!)'!CB5 -> 5
D7: Score op huidig situatie | E7: ='Data (NIET BEWERKEN!!)'!E7 -> 0 | F7: ='Data (NIET BEWERKEN!!)'!F7 -> 0 | G7: ='Data (NIET BEWERKEN!!)'!G7 -> 0 | H7: ='Data (NIET BEWERKEN!!)'!H7 -> 0 | I7: ='Data (NIET BEWERKEN!!)'!I7 -> 0 | J7: ='Data (NIET BEWERKEN!!)'!J7 -> 0 | K7: ='Data (NIET BEWERKEN!!)'!K7 -> 0 | L7: ='Data (NIET BEWERKEN!!)'!L7 -> 0 | ... CB7: ='Data (NIET BEWERKEN!!)'!CB7 -> 0
D8: Subtotaal Gem | O8: =AVERAGE(K7:O7) -> 0 | S8: =AVERAGE(P7:S7) -> 0 | X8: =AVERAGE(T7:X7) -> 0 | AC8: =AVERAGE(Y7:AC7) -> 0 | AH8: =AVERAGE(AD7:AH7) -> 0 | AP8: =AVERAGE(AI7:AP7) -> 0 | AU8: =AVERAGE(AQ7:AU7) -> 0 | AX8: =AVERAGE(V7:AX7) -> 0
D9: Totaal Gem | J9: =AVERAGE(E7:J7) -> 0 | AX9: =AVERAGE(K7:AX7) -> 0 | BM9: =AVERAGE(AY7:BM7) -> 0 | BR9: =AVERAGE(BN7:BR7) -> 0 | BW9: =AVERAGE(BS7:BW7) -> 0 | CB9: =AVERAGE(BX7:CB7) -> 0
D11: Score op ambitie | E11: ='Data (NIET BEWERKEN!!)'!E20 -> 0 | F11: ='Data (NIET BEWERKEN!!)'!F20 -> 0 | G11: ='Data (NIET BEWERKEN!!)'!G20 -> 0 | H11: ='Data (NIET BEWERKEN!!)'!H20 -> 0 | I11: ='Data (NIET BEWERKEN!!)'!I20 -> 0 | J11: ='Data (NIET BEWERKEN!!)'!J20 -> 0 | K11: ='Data (NIET BEWERKEN!!)'!K20 -> 0 | L11: ='Data (NIET BEWERKEN!!)'!L20 -> 0 | ... CB11: ='Data (NIET BEWERKEN!!)'!CB20 -> 0
D12: Subtotaal Gem | O12: =AVERAGE(K11:O11) -> 0 | S12: =AVERAGE(P11:S11) -> 0 | X12: =AVERAGE(T11:X11) -> 0 | AC12: =AVERAGE(Y11:AC11) -> 0 | AH12: =AVERAGE(AD11:AH11) -> 0 | AP12: =AVERAGE(AI11:AP11) -> 0 | AU12: =AVERAGE(AQ11:AU11) -> 0 | AX12: =AVERAGE(V11:AX11) -> 0
D13: Totaal Gem | J13: =AVERAGE(E11:J11) -> 0 | AX13: =AVERAGE(K11:AX11) -> 0 | BM13: =AVERAGE(AY11:BM11) -> 0 | BR13: =AVERAGE(BN11:BR11) -> 0 | BW13: =AVERAGE(BS11:BW11) -> 0 | CB13: =AVERAGE(BX11:CB11) -> 0
D16: Totaal
D34: Categorieën
D67: Domain skills subcategorieën
