Workbook

Sheet Theory
A2: Digital Power Competentiehuis | J2: Competentiegebieden
H3: a

Sheet Questions
B1: Question list
B3: Instructions
B4: Each competency area (6), which can be recognized by the different colours, consists of a number of specific competencies. Determine for each competency where your ambition (desired competency level) lies and where you are now (competency level to date). - Do this by scoring yourself on the indicated scale (see example) - If you have no ambition (yet) for a competence, you keep the score that reflects toward your current competency level. Determine for each competency which description best fits the situation (present/desired). Do not only look at knowledge and skills, but also at the sphere of influence and degree of (personal) leadership in your role with the customer. Create your desired profile based on your ambition! And develop those competencies that give substance to the realization of this ambition. The aim is not to test whether or not you are a good consultant within this domain. The goal is that you develop competencies that match your ambition. Be realistic when filling it out. Only then will you use it to its full potential. Good luck!
C24: For each situation, enter the corresponding value for the most appropriate competency description | E24: Situational competency
B25: Example competence area | C25: Competency level to date | D25: Desired competency level | E25: 1 | F25: 2 | G25: 3 | H25: 4 | I25: 5
B26: Example competency | C26: 2 | D26: 3 | E26: Competency description example: Acts on competency A with customers. | F26: Competency description example: Acts with customers in addition to competency A, also on competency B. | G26: Competency description example: Acts with customers in addition to competency A , B, and also on competency C. | H26: Competency description example: Acts with customers in addition to competency A, B, C, and also on competency D. | I26: Competency description example: Acts with customers in addition to competency A, B, C, D and also on competency E.
B28: Digital Power basic competencies | C28: Competency level to date | D28: Desired competency level | E28: 1 | F28: 2 | G28: 3 | H28: 4 | I28: 5
B29: Learning & reflection | E29: Has a growth mindset | F29: Receives positive and constructive feedback with an open attitude, is able to use this for self-reflection, incorporate it into their own development and undertake the necessary development with training and courses. | G29: In addition to the indicated external stimulus (feedback from others), is able to remain critical of their own knowledge and lack of experience. Takes the necessary actions in this respect and takes control of their own development. | H29: Takes on an exemplary role in the previously indicated competencies and also actively promotes them by taking on a guiding role to juniors and mediors. | I29: Takes on a leadership role in the indicated competencies and actively carries this out in the role of supervisor and/or by taking responsibility within the organisation.
B30: Support & collaboration | E30: Has a collaborative mindset | F30: Is helpful and involved with both internal and external colleagues | G30: Actively seeks cooperation. Both within and outside the team in which they are (temporarily) part of. | H30: Acts like an example in seeking cooperation. Takes responsibility to support others and provides assistance to ensure team members become self-reliant in their work. | I30: -
B31: Entrepreneurial & result-oriented | E31: Has an entrepreneurial & result-oriented mindset | F31: Focused on acting effectively and delivering agreed work on time, within the agreed timeframe. | G31: In addition to the previously mentioned competencies, is able to recognize opportunities and be proactive in helping customers and/or furthering profile of DiP. Is able to translate customer objectives into concrete and practical actions. | H31: In addition to the previously mentioned competencies, able to increase commercial activities (such as increasing hours, generating additional assignments, etc.). Develops projects within DiP and oversees and/or guides them towards the intended result. | I31: In addition to the previously mentioned competencies, is responsible for the development of a specialism within DiP. This includes ensuring expertise in this domain continuously develops and stays up-to-date with the market.
B32: Customer-oriented | E32: Has a customer-oriented mindset | F32: Recognizes customer needs and interests; adopts a helpful attitude and takes the needs and interests of the customer into account in their work. | G32: In addition to the previously mentioned competencies, actively thinks along with the client. Shares insights of the client organization within DiP in order to further expand commercial activities. Actively strives to increase customer satisfaction and improve quality of work. | H32: In addition to the previously mentioned competencies, stimulates and facilitates others to actively act in a customer-oriented manner. Is able to expand customer activity through expertise. Exceeds customer expectations. | I32: In addition to the previously mentioned competencies, bears responsibility for a customer-oriented approach. Is committed to maintaining a high level of customer focus on a structural basis.
B33: Knowledge sharing | E33: Actively learns from the DiP organisation. | F33: Learns from the DiP organization and actively shares own experiences with colleagues. | G33: In addition to the previously stated competencies, actively shares own experiences and knowledge in DiP meet-ups, peer groups and provides training, etc. Also shares knowledge externally in meet-ups, conferences, training courses, blogs, inspiration sessions, etc. | H33: In addition to the previously stated activities, can act as a source of information for other consultants through acquired knowledge and experience. Also contributes to the team spirit. | I33: In addition to the previously mentioned activities, bears responsibility for the level of knowledge sharing. Ensures that knowledge sharing remains up to date in terms of content and frequency.
B34: Coaching & guidance | E34: Has never (in)formally provided coaching or guidance in a professional field | F34: Has followed one or more trainings/courses about coaching and/or guiding in a professional field. | G34: Has informally coached and/or supervised one or more colleagues (within DiP) in the professional field. | H34: Formally supervises one or more junior/medior consultants (within DiP) in their professional development. | I34: Has formally supervised one or more junior/medior/senior consultants in their professional development (within DiP) for more than 4 years.
B36: Ethics and professionalism | C36: Competency level to date | D36: Desired competency level | E36: 0. Unfamiliar (I don't know) 1. Familiar with (I know what can be done) 2. Novice (collaborated) 3. Acceptable (good enough for client projects) 4. Market conforming / good (comparable within DiP and outside DiP) 5. Exceeding market standard 6. Outstanding (outstanding within DiP and outside DiP) Can you be outstanding on assumptions? or e.g. correlation?
B37: Is aware of the existence of the GDPR and other relevant legislation
B38: Is familiar with the legal requirements regarding privacy (GDPR, data storage, data collection, data breach, etc.) and takes these into account in his own work.
B39: Pro-actively advises clients on the legal requirements and implications of privacy.
B40: In addition to the above, also takes ethical considerations and implications into account in his own work. Pay attention to this aspect.
B41: Proactively advises clients on the ethical considerations and implications of choices.
B43: Basic data skills | C43: Competency level to date | D43: Desired competency level | E43: 0. Unfamiliar (I don't know) 1. Familiar with (I know what can be done) 2. Novice (collaborated) 3. Acceptable (good enough for client projects) 4. Market conforming / good (comparable within DiP and outside DiP) 5. Exceeding market standard 6. Outstanding (outstanding within DiP and outside DiP) Can you be outstanding on assumptions? or e.g. correlation?
B44: Is aware of the different types of data and their possibilities/limits Types of data means nominal, ordinal interval and ratio.
B45: Understands data quality and recognizes problems with it. Familiar with various problems and biases that occur in data. For example, incomplete, incorrect, inconsistent and/or outdated.
B46: Also knows the solutions to deal with data quality problems Can apply appropriate solutions to various data quality problems.
B47: Can effectively and efficiently transform/manipulate the data Process and combine data for analysis.From manually in Excel to formulas and code.
B49: Statistics | C49: Competency level to date | D49: Desired competency level | E49: 0. Unfamiliar (I don't know) 1. Familiar with (I know what can be done) 2. Novice (collaborated) 3. Acceptable (good enough for client projects) 4. Market conforming / good (comparable within DiP and outside DiP) 5. Exceeding market standard 6. Outstanding (outstanding within DiP and outside DiP) Can you be outstanding on assumptions? or e.g. correlation?
B50: Assumptions about sample size, distribution, etc. The assumptions used to determine the statistical test. Checking the distribution by means of descriptive statistics such as standard deviation, mode, median, etc.
B51: Confidence Intervals Confidence intervals mean the interval of values between which the result of your study/sample falls.
B52: Statistical tests - when to use which? The different tests such as z-test, t-test, chi-square test that are applied when analyzing an experiment
B53: Correlation Unit of measure to demonstrate static relationship.
B54: Regression Measurement method to different variables to demonstrate correlation and predictive value
B56: Qualitative analysis and research skills | C56: Competency level to date | D56: Desired competency level | E56: 0. Unfamiliar (I don't know) 1. Familiar with (I know what can be done) 2. Novice (collaborated) 3. Acceptable (good enough for client projects) 4. Market conforming / good (comparable within DiP and outside DiP) 5. Exceeding market standard 6. Outstanding (outstanding within DiP and outside DiP) Can you be outstanding on assumptions? or e.g. correlation?
B57: Reliability & validity Familiar with the concepts, can assess studies on this.
B58: Select an appropriate research method for the problem Able to select the right research method for the issue and goal.
B59: Research design Can design research projects taking into account validity, reliability, feasibility and ethics.
B60: Interpreting research results according to value Recognizing what the research results mean for the organization and the actions that can come out of it.
B61: Research skills in business context Able to select the right research method for the issue in relation to the business context with regard to costs, duration and different stakeholder interests.
B63: Metrics and goals | C63: Competency level to date | D63: Desired competency level | E63: 0. Unfamiliar (I don't know) 1. Familiar with (I know what can be done) 2. Novice (collaborated) 3. Acceptable (good enough for client projects) 4. Market conforming / good (comparable within DiP and outside DiP) 5. Exceeding market standard 6. Outstanding (outstanding within DiP and outside DiP) Can you be outstanding on assumptions? or e.g. correlation?
B64: Metrics for usability and user experience The translation of human behavior into metrics at the behavior and attitude level e.g. time on task, task success rate and satisfaction.
B65: Metrics for the customer experience The translation of the customer experience into metrics such as CSAT, NPS or CES.
B66: Metrics connecting strategy with UX/CX metrics Layering metrics at every level (individual, operational, tactical, strategic) in the organization. Are the metrics the drivers of the strategy?
...

Sheet Data (DO NOT EDIT!!)
E2: Digital Power Basic Skills | F2: Digital Power Basic Skills | G2: Digital Power Basic Skills | H2: Digital Power Basic Skills | I2: Digital Power Basic Skills | J2: Digital Power Basic Skills | K2: Domain Skills | L2: Domain Skills | M2: Domain Skills | N2: Domain Skills | O2: Domain Skills | P2: Domain Skills | Q2: Domain Skills | R2: Domain Skills | S2: Domain Skills | T2: Domain Skills | U2: Domain Skills | V2: Domain Skills | W2: Domain Skills | X2: Domain Skills | Y2: Domain Skills | Z2: Domain Skills | AA2: Domain Skills | AB2: Domain Skills | AC2: Domain Skills | AD2: Domain Skills | AE2: Domain Skills | AF2: Domain Skills | AG2: Domain Skills | AH2: Domain Skills | AI2: Domain Skills | AJ2: Domain Skills | AK2: Domain Skills | AL2: Domain Skills | AM2: Domain Skills | AN2: Domain Skills | AO2: Domain Skills | AP2: Domain Skills | AQ2: Domain Skills | AR2: Domain Skills | AS2: Domain Skills | AT2: Domain Skills | AU2: Domain Skills | AV2: Domain Skills | AW2: Domain Skills | AX2: Domain Skills | AY2: Hardskills | AZ2: Hardskills | BA2: Hardskills | BB2: Hardskills | BC2: Hardskills | BD2: Hardskills | BE2: Hardskills | BF2: Hardskills | BG2: Hardskills | BH2: Hardskills | BI2: Hardskills | BJ2: Hardskills | BK2: Hardskills | BL2: Hardskills | BM2: Hardskills | BN2: Basic Consultancy Skills | BO2: Basic Consultancy Skills | BP2: Basic Consultancy Skills | BQ2: Basic Consultancy Skills | BR2: Basic Consultancy Skills | BS2: Business Skills | BT2: Business Skills | BU2: Business Skills | BV2: Business Skills | BW2: Business Skills | BX2: Expert Consultancy Skills | BY2: Expert Consultancy Skills | BZ2: Expert Consultancy Skills | CA2: Expert Consultancy Skills | CB2: Expert Consultancy Skills
K3: Ethics and professionalism | L3: =Questions!$B36 -> Ethics and professionalism | M3: =Questions!$B36 -> Ethics and professionalism | N3: =Questions!$B36 -> Ethics and professionalism | O3: =Questions!$B36 -> Ethics and professionalism | P3: =Questions!$B43 -> Basic data skills | Q3: =Questions!$B43 -> Basic data skills | R3: =Questions!$B43 -> Basic data skills | S3: =Questions!$B43 -> Basic data skills | T3: =Questions!$B49 -> Statistics | U3: =Questions!$B49 -> Statistics | V3: =Questions!$B49 -> Statistics | W3: =Questions!$B49 -> Statistics | X3: =Questions!$B49 -> Statistics | Y3: =Questions!$B56 -> Qualitative analysis and research skills | Z3: =Questions!$B56 -> Qualitative analysis and research skills | AA3: =Questions!$B56 -> Qualitative analysis and research skills | AB3: =Questions!$B56 -> Qualitative analysis and research skills | AC3: =Questions!$B56 -> Qualitative analysis and research skills | AD3: =Questions!$B63 -> Metrics and goals | AE3: =Questions!$B63 -> Metrics and goals | AF3: =Questions!$B63 -> Metrics and goals | AG3: =Questions!$B63 -> Metrics and goals | AH3: =Questions!$B63 -> Metrics and goals | AI3: =Questions!$B70 -> CX theory | AJ3: =Questions!$B70 -> CX theory | AK3: =Questions!$B70 -> CX theory | AL3: =Questions!$B70 -> CX theory | AM3: =Questions!$B70 -> CX theory | AN3: =Questions!$B70 -> CX theory | AO3: =Questions!$B70 -> CX theory | AP3: =Questions!$B70 -> CX theory | AQ3: =Questions!$B80 -> CX knowledge application domain | AR3: =Questions!$B80 -> CX knowledge application domain | AS3: =Questions!$B80 -> CX knowledge application domain | AT3: =Questions!$B80 -> CX knowledge application domain | AU3: =Questions!$B80 -> CX knowledge application domain | AV3: =Questions!$B87 -> Bonus skills | AW3: =Questions!$B87 -> Bonus skills | AX3: =Questions!$B87 -> Bonus skills
E4: Learning & reflection | F4: Support & collaboration | G4: Entrepreneurial & result-oriented | H4: Customer-oriented | I4: Knowledge sharing | J4: Coaching & guidance | K4: Aware | L4: Understands | M4: Advises | N4: Takes into account in own work | O4: Proactively advises | P4: Aware of different types of data and possibilities/limitations | Q4: Understands data quality and recognizes problems | R4: Also knows the solutions to deal with data quality problems | S4: Can effectively and efficiently transform/manipulate the data | T4: Assumptions about sample size, distribution, etc. | U4: Confidence Intervals | V4: Statistical tests | W4: Correlation | X4: Regression | Y4: Reliability & validity | Z4: Selecting appropriate research method | AA4: Research design | AB4: Interpreting results | AC4: Research in a business context | AD4: Metrics for usability and UX | AE4: Metrics for CX | AF4: Metrics connecting strategy with UX/CX metrics | AG4: Translating metrics into concrete measurable definitions | AH4: Metrics for the appropriate level in the organization | AI4: Perception and decision making | AJ4: Optimization process | AK4: CX Maturity models | AL4: Brand, usability, UX, CX | AM4: CX strategy | AN4: Copywriting | UX writing | Content | AO4: Customer Journey Mapping & Personas | AP4: Personalization & segmentation | AQ4: Customer Journey (CXO) | AR4: Marketing Analytics | AS4: eCommerce Analytics | AT4: Product Analytics | AU4: Customer Service Optimalisation | AV4: Design | AW4: Prototyping | AX4: Visual design | AY4: =Questions!K93 -> Customer Journey Mapping | AZ4: =Questions!K94 -> Usability Tests - Formative | BA4: =Questions!K95 -> Usability Test - Summative | BB4: =Questions!K96 -> AB Testing | BC4: =Questions!K97 -> Behavioral Analytics (Web and app analytics tooling) | BD4: =Questions!K98 -> Marketing Analytics | BE4: =Questions!K99 -> Session recordings | BF4: =Questions!K100 -> Heatmaps & Scrollmaps | BG4: =Questions!K101 -> Interviewing (setup & executing interview) | BH4: =Questions!K102 -> Survey Design (setup & executing survey) | BI4: =Questions!K103 -> SQL | BJ4: =Questions!K104 -> Python | BK4: =Questions!K105 -> Javascript | BL4: =Questions!K106 -> R | BM4: =Questions!K107 -> HTML / CSS | BN4: Advising | BO4: Decisive & problem-solving | BP4: Interpersonal communication | BQ4: Expectation management | BR4: Written and oral communication | BS4: Organizational and management identification | BT4: Strategic conceptualization | BU4: Project management | BV4: Change management | BW4: Leadership | BX4: Situational communication | BY4: Goal-oriented & effective communication | BZ4: Decision-making | CA4: Persuading & influencing | CB4: Constructive (negative) feedback & bad news conversations
A5: ID | B5: Name | C5: Function | D5: Specialization | E5: 1 | F5: 2 | G5: 3 | H5: 4 | I5: 5 | J5: 6 | K5: 1 | L5: =K5+1 -> 2 | M5: =L5+1 -> 3 | N5: =M5+1 -> 4 | O5: =N5+1 -> 5 | P5: 1 | Q5: 2 | R5: 3 | S5: 4 | T5: 1 | U5: 2 | V5: 3 | W5: 4 | X5: 5 | Y5: 1 | Z5: 2 | AA5: 3 | AB5: 4 | AC5: 5 | AD5: 1 | AE5: 2 | AF5: 3 | AG5: 4 | AH5: 5 | AI5: 1 | AJ5: 2 | AK5: 3 | AL5: 4 | AM5: 5 | AN5: =AM5+1 -> 6 | AO5: =AN5+1 -> 7 | AP5: =AO5+1 -> 8 | AQ5: 1 | AR5: =AQ5+1 -> 2 | AS5: =AR5+1 -> 3 | AT5: =AS5+1 -> 4 | AU5: =AT5+1 -> 5 | AV5: 1 | AW5: =AV5+1 -> 2 | AX5: =AW5+1 -> 3 | AY5: =Questions!A93 -> 1 | AZ5: =Questions!A94 -> 2 | BA5: =Questions!A95 -> 3 | BB5: =Questions!A96 -> 4 | BC5: 5 | BD5: 6 | BE5: 7 | BF5: 8 | BG5: 9 | BH5: 10 | BI5: 11 | BJ5: 12 | BK5: 13 | BL5: 14 | BM5: 15 | BN5: 1 | BO5: 2 | BP5: 3 | BQ5: 4 | BR5: 5 | BS5: 1 | BT5: 2 | BU5: 3 | BV5: 4 | BW5: 5 | BX5: 1 | BY5: 2 | BZ5: 3 | CA5: 4 | CB5: 5
A6: Current
A7: 1 | B7: You (mandatory) | E7: =Questions!C29 -> 0 | F7: =Questions!C30 -> 0 | G7: =Questions!C31 -> 0 | H7: =Questions!C32 -> 0 | I7: =Questions!C33 -> 0 | J7: =Questions!C34 -> 0 | K7: =Questions!C37 -> 0 | L7: =Questions!C38 -> 0 | M7: =Questions!C39 -> 0 | N7: =Questions!C40 -> 0 | O7: =Questions!C41 -> 0 | P7: =Questions!C44 -> 0 | Q7: =Questions!C45 -> 0 | R7: =Questions!C46 -> 0 | S7: =Questions!C47 -> 0 | T7: =Questions!C50 -> 0 | U7: =Questions!C51 -> 0 | V7: =Questions!C52 -> 0 | W7: =Questions!C53 -> 0 | X7: =Questions!C54 -> 0 | Y7: =Questions!C57 -> 0 | Z7: =Questions!C58 -> 0 | AA7: =Questions!C59 -> 0 | AB7: =Questions!C60 -> 0 | AC7: =Questions!C61 -> 0 | AD7: =Questions!C64 -> 0 | AE7: =Questions!C65 -> 0 | AF7: =Questions!C66 -> 0 | AG7: =Questions!C67 -> 0 | AH7: =Questions!C68 -> 0 | AI7: =Questions!C71 -> 0 | AJ7: =Questions!C72 -> 0 | AK7: =Questions!C73 -> 0 | AL7: =Questions!C74 -> 0 | AM7: =Questions!C75 -> 0 | AN7: =Questions!C76 -> 0 | AO7: =Questions!C77 -> 0 | AP7: =Questions!C78 -> 0 | AQ7: =Questions!C81 -> 0 | AR7: =Questions!C82 -> 0 | AS7: =Questions!C83 -> 0 | AT7: =Questions!C84 -> 0 | AU7: =Questions!C85 -> 0 | AV7: =Questions!C88 -> 0 | AW7: =Questions!C89 -> 0 | AX7: =Questions!C90 -> 0 | AY7: =Questions!C93 -> 0 | AZ7: =Questions!C94 -> 0 | BA7: =Questions!C95 -> 0 | BB7: =Questions!C96 -> 0 | BC7: =Questions!C97 -> 0 | BD7: =Questions!C98 -> 0 | BE7: =Questions!C99 -> 0 | BF7: =Questions!C100 -> 0 | BG7: =Questions!C101 -> 0 | BH7: =Questions!C102 -> 0 | BI7: =Questions!C103 -> 0 | BJ7: =Questions!C104 -> 0 | BK7: =Questions!C105 -> 0 | BL7: =Questions!C106 -> 0 | BM7: =Questions!C107 -> 0 | BN7: =Questions!C110 -> 0 | BO7: =Questions!C111 -> 0 | BP7: =Questions!C112 -> 0 | BQ7: =Questions!C113 -> 0 | BR7: =Questions!C114 -> 0 | BS7: =Questions!C117 -> 0 | BT7: =Questions!C118 -> 0 | BU7: =Questions!C119 -> 0 | BV7: =Questions!C120 -> 0 | BW7: =Questions!C121 -> 0 | BX7: =Questions!C124 -> 0 | BY7: =Questions!C125 -> 0 | BZ7: =Questions!C126 -> 0 | CA7: =Questions!C127 -> 0 | CB7: =Questions!C128 -> 0
A8: 2 | B8: Reviewer 1 (optional)
A9: 3 | B9: Reviewer 2 (optional)
A10: 4
A11: 5
A12: 6
A13: 7
A14: 8
A15: 9
A16: 10
A18: Ambition
A19: ID | B19: Name | C19: Function | D19: Specialization | E19: =E5 -> 1 | F19: =F5 -> 2 | G19: =G5 -> 3 | H19: =H5 -> 4 | I19: =I5 -> 5 | J19: =J5 -> 6 | K19: =K5 -> 1 | L19: =L5 -> 2 | ... CB19: =CB5 -> 5
A20: =A7 -> 1 | B20: =B7 -> You (mandatory) | C20: =C7 -> 0 | D20: =D7 -> 0 | E20: =Questions!D29 -> 0 | F20: =Questions!D30 -> 0 | G20: =Questions!D31 -> 0 | H20: =Questions!D32 -> 0 | I20: =Questions!D33 -> 0 | J20: =Questions!D34 -> 0 | K20: =Questions!D37 -> 0 | L20: =Questions!D38 -> 0 | M20: =Questions!D39 -> 0 | N20: =Questions!D40 -> 0 | O20: =Questions!D41 -> 0 | P20: =Questions!D44 -> 0 | Q20: =Questions!D45 -> 0 | R20: =Questions!D46 -> 0 | S20: =Questions!D47 -> 0 | T20: =Questions!D50 -> 0 | U20: =Questions!D51 -> 0 | V20: =Questions!D52 -> 0 | W20: =Questions!D53 -> 0 | X20: =Questions!D54 -> 0 | Y20: =Questions!D57 -> 0 | Z20: =Questions!D58 -> 0 | AA20: =Questions!D59 -> 0 | AB20: =Questions!D60 -> 0 | AC20: =Questions!D61 -> 0 | AD20: =Questions!D64 -> 0 | AE20: =Questions!D65 -> 0 | AF20: =Questions!D66 -> 0 | AG20: =Questions!D67 -> 0 | AH20: =Questions!D68 -> 0 | AI20: =Questions!D71 -> 0 | AJ20: =Questions!D72 -> 0 | AK20: =Questions!D73 -> 0 | AL20: =Questions!D74 -> 0 | AM20: =Questions!D75 -> 0 | AN20: =Questions!D76 -> 0 | AO20: =Questions!D77 -> 0 | AP20: =Questions!D78 -> 0 | AQ20: =Questions!D81 -> 0 | AR20: =Questions!D82 -> 0 | AS20: =Questions!D83 -> 0 | AT20: =Questions!D84 -> 0 | AU20: =Questions!D85 -> 0 | AV20: =Questions!D88 -> 0 | AW20: =Questions!D89 -> 0 | AX20: =Questions!D90 -> 0 | AY20: =Questions!D93 -> 0 | AZ20: =Questions!D94 -> 0 | BA20: =Questions!D95 -> 0 | BB20: =Questions!D96 -> 0 | BC20: =Questions!D97 -> 0 | BD20: =Questions!D98 -> 0 | BE20: =Questions!D99 -> 0 | BF20: =Questions!D100 -> 0 | BG20: =Questions!D101 -> 0 | BH20: =Questions!D102 -> 0 | BI20: =Questions!D103 -> 0 | BJ20: =Questions!D104 -> 0 | BK20: =Questions!D105 -> 0 | BL20: =Questions!D106 -> 0 | BM20: =Questions!D107 -> 0 | BN20: =Questions!D110 -> 0 | BO20: =Questions!D111 -> 0 | BP20: =Questions!D112 -> 0 | BQ20: =Questions!D113 -> 0 | BR20: =Questions!D114 -> 0 | BS20: =Questions!D117 -> 0 | BT20: =Questions!D118 -> 0 | BU20: =Questions!D119 -> 0 | BV20: =Questions!D120 -> 0 | BW20: =Questions!D121 -> 0 | BX20: =Questions!D124 -> 0 | BY20: =Questions!D125 -> 0 | BZ20: =Questions!D126 -> 0 | CA20: =Questions!D127 -> 0 | CB20: =Questions!D128 -> 0
A21: =A8 -> 2 | B21: =B8 -> Reviewer 1 (optional) | C21: =C8 -> 0 | D21: =D8 -> 0
A22: =A9 -> 3 | B22: =B9 -> Reviewer 2 (optional) | C22: =C9 -> 0 | D22: =D9 -> 0
A23: =A10 -> 4 | B23: =B10 -> 0 | C23: =C10 -> 0 | D23: =D10 -> 0
A24: =A11 -> 5 | B24: =B11 -> 0 | C24: =C11 -> 0 | D24: =D11 -> 0
A25: =A12 -> 6 | B25: =B12 -> 0 | C25: =C12 -> 0 | D25: =D12 -> 0
A26: =A13 -> 7 | B26: =B13 -> 0 | C26: =C13 -> 0 | D26: =D13 -> 0
A27: =A14 -> 8 | B27: =B14 -> 0 | C27: =C14 -> 0 | D27: =D14 -> 0
A28: =A15 -> 9 | B28: =B15 -> 0 | C28: =C15 -> 0 | D28: =D15 -> 0
A29: =A16 -> 10 | B29: =B16 -> 0 | C29: =C16 -> 0 | D29: =D16 -> 0
D32: Competence description | E32: =CONCATENATE("=Vragenlijst!B",E1) -> =Vragenlijst!B | F32: =CONCATENATE("=Vragenlijst!B",F1) -> =Vragenlijst!B | G32: =CONCATENATE("=Vragenlijst!B",G1) -> =Vragenlijst!B | H32: =CONCATENATE("=Vragenlijst!B",H1) -> =Vragenlijst!B | I32: =CONCATENATE("=Vragenlijst!B",I1) -> =Vragenlijst!B | J32: =CONCATENATE("=Vragenlijst!B",J1) -> =Vragenlijst!B | K32: =CONCATENATE("=Vragenlijst!B",K1) -> =Vragenlijst!B | N32: =CONCATENATE("=Vragenlijst!B",N1) -> =Vragenlijst!B | O32: =CONCATENATE("=Vragenlijst!B",O1) -> =Vragenlijst!B | P32: =CONCATENATE("=Vragenlijst!B",P1) -> =Vragenlijst!B | Q32: =CONCATENATE("=Vragenlijst!B",Q1) -> =Vragenlijst!B | R32: =CONCATENATE("=Vragenlijst!B",R1) -> =Vragenlijst!B | S32: =CONCATENATE("=Vragenlijst!B",S1) -> =Vragenlijst!B | T32: =CONCATENATE("=Vragenlijst!B",T1) -> =Vragenlijst!B | U32: =CONCATENATE("=Vragenlijst!B",U1) -> =Vragenlijst!B | ... AX32: =CONCATENATE("=Vragenlijst!B",AX1) -> =Vragenlijst!B | AY32: =CONCATENATE("=Vragenlijst!K",AY1) -> =Vragenlijst!K | AZ32: =CONCATENATE("=Vragenlijst!K",AZ1) -> =Vragenlijst!K | BA32: =CONCATENATE("=Vragenlijst!K",BA1) -> =Vragenlijst!K | BB32: =CONCATENATE("=Vragenlijst!K",BB1) -> =Vragenlijst!K | BC32: =CONCATENATE("=Vragenlijst!K",BC1) -> =Vragenlijst!K | BD32: =CONCATENATE("=Vragenlijst!K",BD1) -> =Vragenlijst!K | BE32: =CONCATENATE("=Vragenlijst!K",BE1) -> =Vragenlijst!K | BF32: =CONCATENATE("=Vragenlijst!K",BF1) -> =Vragenlijst!K | ... BM32: =CONCATENATE("=Vragenlijst!K",BM1) -> =Vragenlijst!K
D34: Current | E34: =CONCATENATE("=Vragenlijst!C",E1) -> =Vragenlijst!C | F34: =CONCATENATE("=Vragenlijst!C",F1) -> =Vragenlijst!C | G34: =CONCATENATE("=Vragenlijst!C",G1) -> =Vragenlijst!C | H34: =CONCATENATE("=Vragenlijst!C",H1) -> =Vragenlijst!C | I34: =CONCATENATE("=Vragenlijst!C",I1) -> =Vragenlijst!C | J34: =CONCATENATE("=Vragenlijst!C",J1) -> =Vragenlijst!C | K34: =CONCATENATE("=Vragenlijst!C",K1) -> =Vragenlijst!C | L34: =CONCATENATE("=Vragenlijst!C",L1) -> =Vragenlijst!C | ... CB34: =CONCATENATE("=Vragenlijst!C",CB1) -> =Vragenlijst!C
D36: Ambition | E36: =CONCATENATE("=Vragenlijst!D",E1) -> =Vragenlijst!D | F36: =CONCATENATE("=Vragenlijst!D",F1) -> =Vragenlijst!D | G36: =CONCATENATE("=Vragenlijst!D",G1) -> =Vragenlijst!D | H36: =CONCATENATE("=Vragenlijst!D",H1) -> =Vragenlijst!D | I36: =CONCATENATE("=Vragenlijst!D",I1) -> =Vragenlijst!D | J36: =CONCATENATE("=Vragenlijst!D",J1) -> =Vragenlijst!D | K36: =CONCATENATE("=Vragenlijst!D",K1) -> =Vragenlijst!D | L36: =CONCATENATE("=Vragenlijst!D",L1) -> =Vragenlijst!D | ... CB36: =CONCATENATE("=Vragenlijst!D",CB1) -> =Vragenlijst!D

Sheet Results (DO NOT EDIT!!)
E2: ='Data (DO NOT EDIT!!)'!E2 -> Digital Power Basic Skills | F2: ='Data (DO NOT EDIT!!)'!F2 -> Digital Power Basic Skills | G2: ='Data (DO NOT EDIT!!)'!G2 -> Digital Power Basic Skills | H2: ='Data (DO NOT EDIT!!)'!H2 -> Digital Power Basic Skills | I2: ='Data (DO NOT EDIT!!)'!I2 -> Digital Power Basic Skills | J2: ='Data (DO NOT EDIT!!)'!J2 -> Digital Power Basic Skills | K2: ='Data (DO NOT EDIT!!)'!K2 -> Domain Skills | L2: ='Data (DO NOT EDIT!!)'!L2 -> Domain Skills | ... AW2: ='Data (DO NOT EDIT!!)'!AW2 -> Domain Skills | AX2: Domain Skills | AY2: ='Data (DO NOT EDIT!!)'!AY2 -> Hardskills | AZ2: ='Data (DO NOT EDIT!!)'!AZ2 -> Hardskills | BA2: ='Data (DO NOT EDIT!!)'!BA2 -> Hardskills | BB2: ='Data (DO NOT EDIT!!)'!BB2 -> Hardskills | BC2: ='Data (DO NOT EDIT!!)'!BC2 -> Hardskills | BD2: ='Data (DO NOT EDIT!!)'!BD2 -> Hardskills | BE2: ='Data (DO NOT EDIT!!)'!BE2 -> Hardskills | BF2: ='Data (DO NOT EDIT!!)'!BF2 -> Hardskills | ... CB2: ='Data (DO NOT EDIT!!)'!CB2 -> Expert Consultancy Skills
K3: Ethics and professionalism | L3: Ethics and professionalism | M3: Ethics and professionalism | N3: Ethics and professionalism | O3: Ethics and professionalism | P3: Basic data skills | Q3: Basic data skills | R3: Basic data skills | S3: Basic data skills | T3: Statistics | U3: Statistics | V3: Statistics | W3: Statistics | X3: Statistics | Y3: Qualitative analysis and research skills | Z3: Qualitative analysis and research skills | AA3: Qualitative analysis and research skills | AB3: Qualitative analysis and research skills | AC3: Qualitative analysis and research skills | AD3: Metrics and goals | AE3: Metrics and goals | AF3: Metrics and goals | AG3: Metrics and goals | AH3: Metrics and goals | AI3: CX theory | AJ3: CX theory | AK3: CX theory | AL3: CX theory | AM3: CX theory | AN3: CX theory | AO3: CX theory | AP3: CX theory | AQ3: CX knowledge application domain | AR3: CX knowledge application domain | AS3: CX knowledge application domain | AT3: CX knowledge application domain | AU3: CX knowledge application domain | AV3: Bonus skills | AW3: Bonus skills | AX3: Bonus skills
E4: Learning & reflection | F4: Support & collaboration | G4: Entrepreneurial & result-oriented | H4: Customer-oriented | I4: Knowledge sharing | J4: Coaching & guidance | K4: ='Data (DO NOT EDIT!!)'!K4 -> Aware | L4: ='Data (DO NOT EDIT!!)'!L4 -> Understands | M4: ='Data (DO NOT EDIT!!)'!M4 -> Advises | N4: ='Data (DO NOT EDIT!!)'!N4 -> Takes into account in own work | O4: ='Data (DO NOT EDIT!!)'!O4 -> Proactively advises | P4: ='Data (DO NOT EDIT!!)'!P4 -> Aware of different types of data and possibilities/limitations | Q4: ='Data (DO NOT EDIT!!)'!Q4 -> Understands data quality and recognizes problems | R4: ='Data (DO NOT EDIT!!)'!R4 -> Also knows the solutions to deal with data quality problems | ... CB4: ='Data (DO NOT EDIT!!)'!CB4 -> Constructive (negative) feedback & bad news conversations
E5: ='Data (DO NOT EDIT!!)'!E5 -> 1 | F5: ='Data (DO NOT EDIT!!)'!F5 -> 2 | G5: ='Data (DO NOT EDIT!!)'!G5 -> 3 | H5: ='Data (DO NOT EDIT!!)'!H5 -> 4 | I5: ='Data (DO NOT EDIT!!)'!I5 -> 5 | J5: ='Data (DO NOT EDIT!!)'!J5 -> 6 | K5: ='Data (DO NOT EDIT!!)'!K5 -> 1 | L5: ='Data (DO NOT EDIT!!)'!L5 -> 2 | ... CB5: ='Data (DO NOT EDIT!!)'!CB5 -> 5
D7: Score current situation | E7: ='Data (DO NOT EDIT!!)'!E7 -> 0 | F7: ='Data (DO NOT EDIT!!)'!F7 -> 0 | G7: ='Data (DO NOT EDIT!!)'!G7 -> 0 | H7: ='Data (DO NOT EDIT!!)'!H7 -> 0 | I7: ='Data (DO NOT EDIT!!)'!I7 -> 0 | J7: ='Data (DO NOT EDIT!!)'!J7 -> 0 | K7: ='Data (DO NOT EDIT!!)'!K7 -> 0 | L7: ='Data (DO NOT EDIT!!)'!L7 -> 0 | ... CB7: ='Data (DO NOT EDIT!!)'!CB7 -> 0
D8: Subtotal average | O8: =AVERAGE(K7:O7) -> 0 | S8: =AVERAGE(P7:S7) -> 0 | X8: =AVERAGE(T7:X7) -> 0 | AC8: =AVERAGE(Y7:AC7) -> 0 | AH8: =AVERAGE(AD7:AH7) -> 0 | AP8: =AVERAGE(AI7:AP7) -> 0 | AU8: =AVERAGE(AQ7:AU7) -> 0 | AX8: =AVERAGE(V7:AX7) -> 0
D9: Total average | J9: =AVERAGE(E7:J7) -> 0 | AX9: =AVERAGE(K7:AX7) -> 0 | BM9: =AVERAGE(AY7:BM7) -> 0 | BR9: =AVERAGE(BN7:BR7) -> 0 | BW9: =AVERAGE(BS7:BW7) -> 0 | CB9: =AVERAGE(BX7:CB7) -> 0
D11: Score ambition | E11: ='Data (DO NOT EDIT!!)'!E20 -> 0 | F11: ='Data (DO NOT EDIT!!)'!F20 -> 0 | G11: ='Data (DO NOT EDIT!!)'!G20 -> 0 | H11: ='Data (DO NOT EDIT!!)'!H20 -> 0 | I11: ='Data (DO NOT EDIT!!)'!I20 -> 0 | J11: ='Data (DO NOT EDIT!!)'!J20 -> 0 | K11: ='Data (DO NOT EDIT!!)'!K20 -> 0 | L11: ='Data (DO NOT EDIT!!)'!L20 -> 0 | ... CB11: ='Data (DO NOT EDIT!!)'!CB20 -> 0
D12: Subtotal average | O12: =AVERAGE(K11:O11) -> 0 | S12: =AVERAGE(P11:S11) -> 0 | X12: =AVERAGE(T11:X11) -> 0 | AC12: =AVERAGE(Y11:AC11) -> 0 | AH12: =AVERAGE(AD11:AH11) -> 0 | AP12: =AVERAGE(AI11:AP11) -> 0 | AU12: =AVERAGE(AQ11:AU11) -> 0 | AX12: =AVERAGE(V11:AX11) -> 0
D13: Total average | J13: =AVERAGE(E11:J11) -> 0 | AX13: =AVERAGE(K11:AX11) -> 0 | BM13: =AVERAGE(AY11:BM11) -> 0 | BR13: =AVERAGE(BN11:BR11) -> 0 | BW13: =AVERAGE(BS11:BW11) -> 0 | CB13: =AVERAGE(BX11:CB11) -> 0
D16: Total
D34: Categories
D67: Domain skills subcategories
