Workbook

Sheet Questions
A1: Question list
A3: Example competence area | B3: For each situation, enter the corresponding value for the most appropriate competency description | F3: Instructions
A4: Example competency | B4: Competency level to date | C4: Desired competency level | D4: Input value | F4: Each competency area (6), which can be recognized by the different colours, consists of a number of specific competencies. Determine for each competency where your ambition (desired competency level) lies and where you are now (competency level to date). - Do this by scoring yourself on the indicated scale (see example) - If you have no ambition (yet) for a competence, you keep the score that reflects toward your current competency level. Determine for each competency which description best fits the situation (present/desired). Do not only look at knowledge and skills, but also at the sphere of influence and degree of (personal) leadership in your role with the customer. Create your desired profile based on your ambition! And develop those competencies that give substance to the realization of this ambition. The aim is not to test whether or not you are a good consultant within this domain. The goal is that you develop competencies that match your ambition. Be realistic when filling it out. Only then will you use it to its full potential. Good luck!
A5: Competency description example: Acts on competency A with customers. | D5: 1
A6: Competency description example: Acts with customers in addition to competency A, also on competency B. | B6: 3 | D6: 2
A7: Competency description example: Acts with customers in addition to competency A , B, and also on competency C. | B7: 3 | C7: 5 | D7: 3
A8: Competency description example: Acts with customers in addition to competency A, B, C, and also on competency D. | C8: 4 | D8: 4
A9: Competency description example: Acts with customers in addition to competency A, B, C, D and also on competency E. | D9: 5
A11: Digital Power basic competencies
A12: Learning & reflection | B12: Competency level to date | C12: Desired competency level | D12: Input value
A13: Has a growth mindset | D13: 1
A14: Receives positive and constructive feedback with an open attitude, is able to use this for self-reflection, incorporate it into their own development and undertake the necessary development with training and courses. | D14: 2
A15: In addition to the indicated external stimulus (feedback from others), is able to remain critical of their own knowledge and lack of experience. Takes the necessary actions in this respect and takes control of their own development. | D15: 3
A16: Takes on an exemplary role in the previously indicated competencies and also actively promotes them by taking on a guiding role to juniors and mediors. | D16: 4
A17: Takes on a leadership role in the indicated competencies and actively carries this out in the role of supervisor and/or by taking responsibility within the organisation. | D17: 5
A19: Support & collaboration | B19: Competency level to date | C19: Desired competency level | D19: Input value
A20: Has a collaborative mindset | D20: 1
A21: Is helpful and involved with both internal and external colleagues | D21: 2
A22: Actively seeks cooperation. Both within and outside the team that they are (temporarily) part of. | D22: 3
A23: Acts like an example in seeking cooperation. Takes responsibility to support others and provides assistance to ensure team members become self-reliant in their work. | D23: 4
A24: - | D24: 5
A26: Entrepreneurial & result-oriented | B26: Competency level to date | C26: Desired competency level | D26: Input value
A27: Has an entrepreneurial & result-oriented mindset | D27: 1
A28: Focused on acting effectively and delivering agreed work on time, within the agreed timeframe. | D28: 2
A29: In addition to the previously mentioned competencies, is able to recognize opportunities and be proactive in helping customers and/or furthering profile of DiP. Is able to translate customer objectives into concrete and practical actions. | D29: 3
A30: In addition to the previously mentioned competencies, able to increase commercial activities (such as increasing hours, generating additional assignments, etc.). Develops projects within DiP and oversees and/or guides them towards the intended result. | D30: 4
A31: In addition to the previously mentioned competencies, is responsible for the development of a specialism within DiP. This includes ensuring expertise in this domain continuously develops and stays up-to-date with the market. | D31: 5
A33: Customer-oriented | B33: Competency level to date | C33: Desired competency level | D33: Input value
A34: Has a customer-oriented mindset | D34: 1
A35: Recognizes customer needs and interests; adopts a helpful attitude and takes the needs and interests of the customer into account in their work. | D35: 2
A36: In addition to the previously mentioned competencies, actively thinks along with the client. Shares insights of the client organization within DiP in order to further expand commercial activities. Actively strives to increase customer satisfaction and improve quality of work. | D36: 3
A37: In addition to the previously mentioned competencies, stimulates and facilitates others to actively act in a customer-oriented manner. Is able to expand customer activity through expertise. Exceeds customer expectations. | D37: 4
A38: In addition to the previously mentioned competencies, bears responsibility for a customer-oriented approach. Is committed to maintaining a high level of customer focus on a structural basis. | D38: 5
A40: Knowledge sharing | B40: Competency level to date | C40: Desired competency level | D40: Input value
A41: Actively learns from the DiP organisation. | D41: 1
A42: Learns from the DiP organization and actively shares own experiences with colleagues. | D42: 2
A43: In addition to the previously stated competencies, actively shares own experiences and knowledge in DiP meet-ups, peer groups and provides training, etc. Also shares knowledge externally in meet-ups, conferences, training courses, blogs, inspiration sessions, etc. | D43: 3
A44: In addition to the previously stated activities, can act as a source of information for other consultants through acquired knowledge and experience. Also contributes to the team spirit. | D44: 4
A45: In addition to the previously mentioned activities, bears responsibility for the level of knowledge sharing. Ensures that knowledge sharing remains up to date in terms of content and frequency. | D45: 5
A47: Coaching & guidance | B47: Competency level to date | C47: Desired competency level | D47: Input value
...

Sheet Theory
A2: Digital Power Competentiehuis | J2: Competentiegebieden

Sheet Data (DO NOT EDIT!!)
E1: Digital Power Basic Skills | F1: Digital Power Basic Skills | G1: Digital Power Basic Skills | H1: Digital Power Basic Skills | I1: Digital Power Basic Skills | J1: Digital Power Basic Skills | K1: Domain Skills | L1: Domain Skills | M1: Domain Skills | N1: Domein Skills | O1: Domein Skills | P1: Domein Skills | Q1: Hardskills | R1: Hardskills | S1: Hardskills | T1: Hardskills | U1: Hardskills | V1: Hardskills | W1: Basic Consultancy Skills | X1: Basic Consultancy Skills | Y1: Basic Consultancy Skills | Z1: Basic Consultancy Skills | AA1: Basic Consultancy Skills | AB1: Business Skills | AC1: Business Skills | AD1: Business Skills | AE1: Business Skills | AF1: Business Skills | AG1: Expert Consultancy Skills | AH1: Expert Consultancy Skills | AI1: Expert Consultancy Skills | AJ1: Expert Consultancy Skills | AK1: Expert Consultancy Skills
E2: Learning & reflection | F2: Support & collaboration | G2: Entrepreneurial & result-oriented | H2: Customer-oriented | I2: Knowledge sharing | J2: Coaching & guidance | K2: Communication developers/ analysts | L2: Tagging trends in domain | M2: Requirements | Q2: Analytics (management/ admin) knowledge | R2: Tag management | S2: Data structures, tagplan, datalayer | T2: Debugging | U2: Programming | W2: Advising | X2: Decisive & problem-solving | Y2: Interpersonal communication | Z2: Expectation management | AA2: Written and oral communication | AB2: Organizational and management identification | AC2: Strategic conceptualization | AD2: Project management | AE2: Change management | AF2: Leadership | AG2: Situational communication | AH2: Goal-oriented & effective communication | AI2: Decision-making | AJ2: Persuading & influencing | AK2: Constructive (negative) feedback & bad news conversations
A3: ID | B3: Name | C3: Function | D3: Specialization | E3: 1 | F3: 2 | G3: 3 | H3: 4 | I3: 5 | J3: 6 | K3: 1 | L3: 2 | M3: 3 | N3: 4 | O3: 5 | P3: 6 | Q3: 1 | R3: 2 | S3: 3 | T3: 4 | U3: 5 | V3: 6 | W3: 1 | X3: 2 | Y3: 3 | Z3: 4 | AA3: 5 | AB3: 1 | AC3: 2 | AD3: 3 | AE3: 4 | AF3: 5 | AG3: 1 | AH3: 2 | AI3: 3 | AJ3: 4 | AK3: 5
A4: Current
A5: 1 | B5: You (mandatory) | E5: =SUM(Questions!$B13:$B17)/COUNT(Questions!$B13:$B17) -> #DIV/0! | F5: =SUM(Questions!$B20:$B24)/COUNT(Questions!$B20:$B24) -> #DIV/0! | G5: =SUM(Questions!$B27:$B31)/COUNT(Questions!$B27:$B31) -> #DIV/0! | H5: =SUM(Questions!$B34:$B38)/COUNT(Questions!$B34:$B38) -> #DIV/0! | I5: =SUM(Questions!$B41:$B45)/COUNT(Questions!$B41:$B45) -> #DIV/0! | J5: =SUM(Questions!$B48:$B52)/COUNT(Questions!$B48:$B52) -> #DIV/0! | K5: =SUM(Questions!$B56:$B60)/COUNT(Questions!$B56:$B60) -> #DIV/0! | L5: =SUM(Questions!$B63:$B67)/COUNT(Questions!$B63:$B67) -> #DIV/0! | M5: =SUM(Questions!$B70:$B74)/COUNT(Questions!$B70:$B74) -> #DIV/0! | N5: =SUM(Questions!$B77:$B81)/COUNT(Questions!$B77:$B81) -> #DIV/0! | O5: =SUM(Questions!$B84:$B88)/COUNT(Questions!$B84:$B88) -> #DIV/0! | P5: =SUM(Questions!$B91:$B95)/COUNT(Questions!$B91:$B95) -> #DIV/0! | Q5: =SUM(Questions!$B99:$B103)/COUNT(Questions!$B99:$B103) -> #DIV/0! | R5: =SUM(Questions!$B106:$B110)/COUNT(Questions!$B106:$B110) -> #DIV/0! | S5: =SUM(Questions!$B113:$B117)/COUNT(Questions!$B113:$B117) -> #DIV/0! | T5: =SUM(Questions!$B120:$B124)/COUNT(Questions!$B120:$B124) -> #DIV/0! | U5: =SUM(Questions!$B127:$B131)/COUNT(Questions!$B127:$B131) -> #DIV/0! | V5: =SUM(Questions!$B134:$B138)/COUNT(Questions!$B134:$B138) -> #DIV/0! | W5: =SUM(Questions!$B142:$B146)/COUNT(Questions!$B142:$B146) -> #DIV/0! | X5: =SUM(Questions!$B149:$B153)/COUNT(Questions!$B149:$B153) -> #DIV/0! | Y5: =SUM(Questions!$B156:$B160)/COUNT(Questions!$B156:$B160) -> #DIV/0! | Z5: =SUM(Questions!$B163:$B167)/COUNT(Questions!$B163:$B167) -> #DIV/0! | AA5: =SUM(Questions!$B170:$B174)/COUNT(Questions!$B170:$B174) -> #DIV/0! | AB5: =SUM(Questions!$B178:$B182)/COUNT(Questions!$B178:$B182) -> #DIV/0! | AC5: =SUM(Questions!$B185:$B189)/COUNT(Questions!$B185:$B189) -> #DIV/0! | AD5: =SUM(Questions!$B192:$B196)/COUNT(Questions!$B192:$B196) -> #DIV/0! | AE5: =SUM(Questions!$B199:$B203)/COUNT(Questions!$B199:$B203) -> #DIV/0! | AF5: =SUM(Questions!$B206:$B210)/COUNT(Questions!$B206:$B210) -> #DIV/0! | AG5: =SUM(Questions!$B214:$B218)/COUNT(Questions!$B214:$B218) -> #DIV/0! | AH5: =SUM(Questions!$B221:$B225)/COUNT(Questions!$B221:$B225) -> #DIV/0! | AI5: =SUM(Questions!$B228:$B232)/COUNT(Questions!$B228:$B232) -> #DIV/0! | AJ5: =SUM(Questions!$B235:$B239)/COUNT(Questions!$B235:$B239) -> #DIV/0! | AK5: =SUM(Questions!$B242:$B246)/COUNT(Questions!$B242:$B246) -> #DIV/0!
A6: 2 | B6: Reviewer 1 (optional)
A7: 3 | B7: Reviewer 2 (optional)
A8: 4
A9: 5
A10: 6
A11: 7
A12: 8
A13: 9
A14: 10
A16: Ambition
A17: ID | B17: Name | C17: Function | D17: Specialization | E17: 1 | F17: 2 | G17: 3 | H17: 4 | I17: 5 | J17: 6 | K17: 1 | L17: 2 | M17: 3 | N17: 4 | O17: 5 | P17: 6 | Q17: 1 | R17: 2 | S17: 3 | T17: 4 | U17: 5 | V17: 6 | W17: 1 | X17: 2 | Y17: 3 | Z17: 4 | AA17: 5 | AB17: 1 | AC17: 2 | AD17: 3 | AE17: 4 | AF17: 5 | AG17: 1 | AH17: 2 | AI17: 3 | AJ17: 4 | AK17: 5
A18: 1 | B18: You (mandatory) | C18: 0 | D18: 0 | E18: =SUM(Questions!$C13:$C17)/COUNT(Questions!$C13:$C17) -> #DIV/0! | F18: =SUM(Questions!$C20:$C24)/COUNT(Questions!$C20:$C24) -> #DIV/0! | G18: =SUM(Questions!$C27:$C31)/COUNT(Questions!$C27:$C31) -> #DIV/0! | H18: =SUM(Questions!$C34:$C38)/COUNT(Questions!$C34:$C38) -> #DIV/0! | I18: =SUM(Questions!$C41:$C45)/COUNT(Questions!$C41:$C45) -> #DIV/0! | J18: =SUM(Questions!$C48:$C52)/COUNT(Questions!$C48:$C52) -> #DIV/0! | K18: =SUM(Questions!$C56:$C60)/COUNT(Questions!$C56:$C60) -> #DIV/0! | L18: =SUM(Questions!$C63:$C67)/COUNT(Questions!$C63:$C67) -> #DIV/0! | M18: =SUM(Questions!$C70:$C74)/COUNT(Questions!$C70:$C74) -> #DIV/0! | N18: =SUM(Questions!$C77:$C81)/COUNT(Questions!$C77:$C81) -> #DIV/0! | O18: =SUM(Questions!$C84:$C88)/COUNT(Questions!$C84:$C88) -> #DIV/0! | P18: =SUM(Questions!$C91:$C95)/COUNT(Questions!$C91:$C95) -> #DIV/0! | Q18: =SUM(Questions!$C99:$C103)/COUNT(Questions!$C99:$C103) -> #DIV/0! | R18: =SUM(Questions!$C106:$C110)/COUNT(Questions!$C106:$C110) -> #DIV/0! | S18: =SUM(Questions!$C113:$C117)/COUNT(Questions!$C113:$C117) -> #DIV/0! | T18: =SUM(Questions!$C120:$C124)/COUNT(Questions!$C120:$C124) -> #DIV/0! | U18: =SUM(Questions!$C127:$C131)/COUNT(Questions!$C127:$C131) -> #DIV/0! | V18: =SUM(Questions!$C134:$C138)/COUNT(Questions!$C134:$C138) -> #DIV/0! | W18: =SUM(Questions!$C142:$C146)/COUNT(Questions!$C142:$C146) -> #DIV/0! | X18: =SUM(Questions!$C149:$C153)/COUNT(Questions!$C149:$C153) -> #DIV/0! | Y18: =SUM(Questions!$C156:$C160)/COUNT(Questions!$C156:$C160) -> #DIV/0! | Z18: =SUM(Questions!$C163:$C167)/COUNT(Questions!$C163:$C167) -> #DIV/0! | AA18: =SUM(Questions!$C170:$C174)/COUNT(Questions!$C170:$C174) -> #DIV/0! | AB18: =SUM(Questions!$C178:$C182)/COUNT(Questions!$C178:$C182) -> #DIV/0! | AC18: =SUM(Questions!$C185:$C189)/COUNT(Questions!$C185:$C189) -> #DIV/0! | AD18: =SUM(Questions!$C192:$C196)/COUNT(Questions!$C192:$C196) -> #DIV/0! | AE18: =SUM(Questions!$C199:$C203)/COUNT(Questions!$C199:$C203) -> #DIV/0! | AF18: =SUM(Questions!$C206:$C210)/COUNT(Questions!$C206:$C210) -> #DIV/0! | AG18: =SUM(Questions!$C214:$C218)/COUNT(Questions!$C214:$C218) -> #DIV/0! | AH18: =SUM(Questions!$C221:$C225)/COUNT(Questions!$C221:$C225) -> #DIV/0! | AI18: =SUM(Questions!$C228:$C232)/COUNT(Questions!$C228:$C232) -> #DIV/0! | AJ18: =SUM(Questions!$C235:$C239)/COUNT(Questions!$C235:$C239) -> #DIV/0! | AK18: =SUM(Questions!$C242:$C246)/COUNT(Questions!$C242:$C246) -> #DIV/0!
A19: 2 | B19: Reviewer 1 (optional) | C19: 0 | D19: 0
A20: 3 | B20: Reviewer 2 (optional) | C20: 0 | D20: 0
A21: 4 | B21: 0 | C21: 0 | D21: 0
A22: =A9 -> 5 | B22: =B9 -> 0 | C22: =C9 -> 0 | D22: =D9 -> 0
A23: =A10 -> 6 | B23: =B10 -> 0 | C23: =C10 -> 0 | D23: =D10 -> 0
A24: =A11 -> 7 | B24: =B11 -> 0 | C24: =C11 -> 0 | D24: =D11 -> 0
A25: =A12 -> 8 | B25: =B12 -> 0 | C25: =C12 -> 0 | D25: =D12 -> 0
A26: =A13 -> 9 | B26: =B13 -> 0 | C26: =C13 -> 0 | D26: =D13 -> 0
A27: =A14 -> 10 | B27: =B14 -> 0 | C27: =C14 -> 0 | D27: =D14 -> 0

Sheet Results (DO NOT EDIT!!)
B1: ='Data (DO NOT EDIT!!)'!E1 -> Digital Power Basic Skills | C1: ='Data (DO NOT EDIT!!)'!F1 -> Digital Power Basic Skills | D1: ='Data (DO NOT EDIT!!)'!G1 -> Digital Power Basic Skills | E1: ='Data (DO NOT EDIT!!)'!H1 -> Digital Power Basic Skills | F1: ='Data (DO NOT EDIT!!)'!I1 -> Digital Power Basic Skills | G1: ='Data (DO NOT EDIT!!)'!J1 -> Digital Power Basic Skills | H1: ='Data (DO NOT EDIT!!)'!K1 -> Domain Skills | I1: ='Data (DO NOT EDIT!!)'!L1 -> Domain Skills | ... AH1: ='Data (DO NOT EDIT!!)'!AK1 -> Expert Consultancy Skills
B2: ='Data (DO NOT EDIT!!)'!E2 -> Learning & reflection | C2: ='Data (DO NOT EDIT!!)'!F2 -> Support & collaboration | D2: ='Data (DO NOT EDIT!!)'!G2 -> Entrepreneurial & result-oriented | E2: ='Data (DO NOT EDIT!!)'!H2 -> Customer-oriented | F2: ='Data (DO NOT EDIT!!)'!I2 -> Knowledge sharing | G2: ='Data (DO NOT EDIT!!)'!J2 -> Coaching & guidance | H2: ='Data (DO NOT EDIT!!)'!K2 -> Communication developers/ analysts | I2: ='Data (DO NOT EDIT!!)'!L2 -> Tagging trends in domain | ... AH2: ='Data (DO NOT EDIT!!)'!AK2 -> Constructive (negative) feedback & bad news conversations
B3: 1 | C3: 2 | D3: 3 | E3: 4 | F3: 5 | G3: 6 | H3: 1 | I3: 2 | J3: 3 | K3: 10 | L3: 11 | M3: 12 | N3: 1 | O3: 2 | P3: 3 | Q3: 4 | R3: 5 | S3: 18 | T3: 1 | U3: 2 | V3: 3 | W3: 4 | X3: 5 | Y3: 1 | Z3: 2 | AA3: 3 | AB3: 4 | AC3: 5 | AD3: 1 | AE3: 2 | AF3: 3 | AG3: 4 | AH3: 5
A4: Score current situation | B4: ='Data (DO NOT EDIT!!)'!E5 -> #DIV/0! | C4: ='Data (DO NOT EDIT!!)'!F5 -> #DIV/0! | D4: ='Data (DO NOT EDIT!!)'!G5 -> #DIV/0! | E4: ='Data (DO NOT EDIT!!)'!H5 -> #DIV/0! | F4: ='Data (DO NOT EDIT!!)'!I5 -> #DIV/0! | G4: ='Data (DO NOT EDIT!!)'!J5 -> #DIV/0! | H4: ='Data (DO NOT EDIT!!)'!K5 -> #DIV/0! | I4: ='Data (DO NOT EDIT!!)'!L5 -> #DIV/0! | ... AH4: ='Data (DO NOT EDIT!!)'!AK5 -> #DIV/0!
A5: Total average | G5: =AVERAGE(B4:G4) -> #DIV/0! | J5: =AVERAGE(H4:J4) -> #DIV/0! | R5: =AVERAGE(N4:R4) -> #DIV/0! | X5: =AVERAGE(T4:X4) -> #DIV/0! | AC5: =AVERAGE(Y4:AC4) -> #DIV/0! | AH5: =AVERAGE(AD4:AH4) -> #DIV/0!
A7: Score ambition | B7: ='Data (DO NOT EDIT!!)'!E18 -> #DIV/0! | C7: ='Data (DO NOT EDIT!!)'!F18 -> #DIV/0! | D7: ='Data (DO NOT EDIT!!)'!G18 -> #DIV/0! | E7: ='Data (DO NOT EDIT!!)'!H18 -> #DIV/0! | F7: ='Data (DO NOT EDIT!!)'!I18 -> #DIV/0! | G7: ='Data (DO NOT EDIT!!)'!J18 -> #DIV/0! | H7: ='Data (DO NOT EDIT!!)'!K18 -> #DIV/0! | I7: ='Data (DO NOT EDIT!!)'!L18 -> #DIV/0! | ... AH7: ='Data (DO NOT EDIT!!)'!AK18 -> #DIV/0!
A8: Total average | G8: =AVERAGE(B7:G7) -> #DIV/0! | J8: =AVERAGE(H7:J7) -> #DIV/0! | R8: =AVERAGE(N7:R7) -> #DIV/0! | X8: =AVERAGE(T7:X7) -> #DIV/0! | AC8: =AVERAGE(Y7:AC7) -> #DIV/0! | AH8: =AVERAGE(AD7:AH7) -> #DIV/0!
